<sdf version='1.7'>
  <world name='default'>
    <light name='sun' type='directional'>
      <cast_shadows>1</cast_shadows>
      <pose>0 0 10 0 -0 0</pose>
      <diffuse>0.8 0.8 0.8 1</diffuse>
      <specular>0.2 0.2 0.2 1</specular>
      <attenuation>
        <range>1000</range>
        <constant>0.9</constant>
        <linear>0.01</linear>
        <quadratic>0.001</quadratic>
      </attenuation>
      <direction>-0.5 0.1 -0.9</direction>
      <spot>
        <inner_angle>0</inner_angle>
        <outer_angle>0</outer_angle>
        <falloff>0</falloff>
      </spot>
    </light>
    <model name='ground_plane'>
      <static>1</static>
      <link name='link'>
        <collision name='collision'>
          <geometry>
            <plane>
              <normal>0 0 1</normal>
              <size>100 100</size>
            </plane>
          </geometry>
          <surface>
            <contact>
              <collide_bitmask>65535</collide_bitmask>
              <ode/>
            </contact>
            <friction>
              <ode>
                <mu>100</mu>
                <mu2>50</mu2>
              </ode>
              <torsional>
                <ode/>
              </torsional>
            </friction>
            <bounce/>
          </surface>
          <max_contacts>10</max_contacts>
        </collision>
        <visual name='visual'>
          <cast_shadows>0</cast_shadows>
          <geometry>
            <plane>
              <normal>0 0 1</normal>
              <size>100 100</size>
            </plane>
          </geometry>
          <material>
            <script>
              <uri>file://media/materials/scripts/gazebo.material</uri>
              <name>Gazebo/Grey</name>
            </script>
          </material>
        </visual>
        <self_collide>0</self_collide>
        <enable_wind>0</enable_wind>
        <kinematic>0</kinematic>
      </link>
    </model>
    <gravity>0 0 -9.8</gravity>
    <magnetic_field>6e-06 2.3e-05 -4.2e-05</magnetic_field>
    <atmosphere type='adiabatic'/>
    <physics type='ode'>
      <max_step_size>0.001</max_step_size>
      <real_time_factor>1</real_time_factor>
      <real_time_update_rate>1000</real_time_update_rate>
    </physics>
    <scene>
      <ambient>0.4 0.4 0.4 1</ambient>
      <background>0.7 0.7 0.7 1</background>
      <shadows>1</shadows>
    </scene>
    <wind/>
    <spherical_coordinates>
      <surface_model>EARTH_WGS84</surface_model>
      <latitude_deg>0</latitude_deg>
      <longitude_deg>0</longitude_deg>
      <elevation>0</elevation>
      <heading_deg>0</heading_deg>
    </spherical_coordinates>
    <model name='robot'>
      <link name='base_link'>
        <inertial>
          <pose>-0.082202 0.081078 0.514938 0 -0 0</pose>
          <mass>3.25338</mass>
          <inertia>
            <ixx>0.51377</ixx>
            <ixy>-0.00420458</ixy>
            <ixz>-0.0319455</ixz>
            <iyy>0.505296</iyy>
            <iyz>-0.0634148</iyz>
            <izz>0.0236301</izz>
          </inertia>
        </inertial>
        <collision name='base_link_collision'>
          <pose>0 0 0 0 -0 0</pose>
          <geometry>
            <mesh>
              <scale>1 1 1</scale>
              <uri>/home/sandisk/koyo_ws/stretch_ws/src/stretch_ros/stretch_description/meshes/base_link.STL</uri>
            </mesh>
          </geometry>
          <surface>
            <contact>
              <ode/>
            </contact>
            <friction>
              <ode/>
              <torsional>
                <ode/>
              </torsional>
            </friction>
            <bounce/>
          </surface>
          <max_contacts>10</max_contacts>
        </collision>
        <collision name='base_link_fixed_joint_lump__caster_link_collision_1'>
          <pose>-0.245 0 0.032 -1.5708 0 0</pose>
          <geometry>
            <sphere>
              <radius>0.032</radius>
            </sphere>
          </geometry>
          <surface>
            <contact>
              <ode>
                <min_depth>0.001</min_depth>
              </ode>
            </contact>
            <friction>
              <ode>
                <mu>0</mu>
                <mu2>0</mu2>
              </ode>
              <torsional>
                <ode/>
              </torsional>
            </friction>
            <bounce/>
          </surface>
          <max_contacts>10</max_contacts>
        </collision>
        <collision name='base_link_fixed_joint_lump__link_aruco_left_base_collision_2'>
          <pose>-0.005 0.130497 0.159748 0 0 -1.5708</pose>
          <geometry>
            <mesh>
              <scale>1 1 1</scale>
              <uri>/home/sandisk/koyo_ws/stretch_ws/src/stretch_ros/stretch_description/meshes/link_aruco_left_base.STL</uri>
            </mesh>
          </geometry>
          <surface>
            <contact>
              <ode/>
            </contact>
            <friction>
              <ode/>
              <torsional>
                <ode/>
              </torsional>
            </friction>
            <bounce/>
          </surface>
          <max_contacts>10</max_contacts>
        </collision>
        <collision name='base_link_fixed_joint_lump__link_aruco_right_base_collision_3'>
          <pose>-0.001503 -0.130497 0.159748 0 0 -1.5708</pose>
          <geometry>
            <mesh>
              <scale>1 1 1</scale>
              <uri>/home/sandisk/koyo_ws/stretch_ws/src/stretch_ros/stretch_description/meshes/link_aruco_right_base.STL</uri>
            </mesh>
          </geometry>
          <surface>
            <contact>
              <ode/>
            </contact>
            <friction>
              <ode/>
              <torsional>
                <ode/>
              </torsional>
            </friction>
            <bounce/>
          </surface>
          <max_contacts>10</max_contacts>
        </collision>
        <collision name='base_link_fixed_joint_lump__laser_collision_4'>
          <pose>0.004 0 0.1664 0 0 -3.14159</pose>
          <geometry>
            <mesh>
              <scale>1 1 1</scale>
              <uri>/home/sandisk/koyo_ws/stretch_ws/src/stretch_ros/stretch_description/meshes/laser.STL</uri>
            </mesh>
          </geometry>
          <surface>
            <contact>
              <ode/>
            </contact>
            <friction>
              <ode/>
              <torsional>
                <ode/>
              </torsional>
            </friction>
            <bounce/>
          </surface>
          <max_contacts>10</max_contacts>
        </collision>
        <collision name='base_link_fixed_joint_lump__link_mast_collision_5'>
          <pose>-0.067 0.135 0.0284 1.5708 -0 0</pose>
          <geometry>
            <mesh>
              <scale>1 1 1</scale>
              <uri>/home/sandisk/koyo_ws/stretch_ws/src/stretch_ros/stretch_description/meshes/link_mast.STL</uri>
            </mesh>
          </geometry>
          <surface>
            <contact>
              <ode/>
            </contact>
            <friction>
              <ode/>
              <torsional>
                <ode/>
              </torsional>
            </friction>
            <bounce/>
          </surface>
          <max_contacts>10</max_contacts>
        </collision>
        <collision name='base_link_fixed_joint_lump__link_head_collision_6'>
          <pose>-0.067 0.134995 1.3584 7e-06 4e-06 -1.5708</pose>
          <geometry>
            <mesh>
              <scale>1 1 1</scale>
              <uri>/home/sandisk/koyo_ws/stretch_ws/src/stretch_ros/stretch_description/meshes/link_head.STL</uri>
            </mesh>
          </geometry>
          <surface>
            <contact>
              <ode/>
            </contact>
            <friction>
              <ode>
                <mu>100</mu>
                <mu2>200</mu2>
              </ode>
              <torsional>
                <ode/>
              </torsional>
            </friction>
            <bounce/>
          </surface>
          <max_contacts>10</max_contacts>
        </collision>
        <collision name='base_link_fixed_joint_lump__respeaker_base_collision_7'>
          <pose>-0.067 0.131964 1.40076 3e-06 2e-06 -0.698132</pose>
          <geometry>
            <mesh>
              <scale>1 1 1</scale>
              <uri>/home/sandisk/koyo_ws/stretch_ws/src/stretch_ros/stretch_description/meshes/respeaker_base.STL</uri>
            </mesh>
          </geometry>
          <surface>
            <contact>
              <ode/>
            </contact>
            <friction>
              <ode/>
              <torsional>
                <ode/>
              </torsional>
            </friction>
            <bounce/>
          </surface>
          <max_contacts>10</max_contacts>
        </collision>
        <visual name='base_link_visual'>
          <pose>0 0 0 0 -0 0</pose>
          <geometry>
            <mesh>
              <scale>1 1 1</scale>
              <uri>/home/sandisk/koyo_ws/stretch_ws/src/stretch_ros/stretch_description/meshes/base_link.STL</uri>
            </mesh>
          </geometry>
          <material>
            <script>
              <name>Gazebo/Gray</name>
              <uri>file://media/materials/scripts/gazebo.material</uri>
            </script>
          </material>
        </visual>
        <visual name='base_link_fixed_joint_lump__caster_link_visual_1'>
          <pose>-0.245 0 0.032 -1.5708 0 0</pose>
          <geometry>
            <mesh>
              <scale>1 1 1</scale>
              <uri>/home/sandisk/koyo_ws/stretch_ws/src/stretch_ros/stretch_description/meshes/omni_wheel_m.STL</uri>
            </mesh>
          </geometry>
          <material>
            <script>
              <name>Gazebo/Blue</name>
              <uri>file://media/materials/scripts/gazebo.material</uri>
            </script>
          </material>
        </visual>
        <visual name='base_link_fixed_joint_lump__link_aruco_left_base_visual_2'>
          <pose>-0.005 0.130497 0.159748 0 0 -1.5708</pose>
          <geometry>
            <mesh>
              <scale>1 1 1</scale>
              <uri>/home/sandisk/koyo_ws/stretch_ws/src/stretch_ros/stretch_description/meshes/link_aruco_left_base.STL</uri>
            </mesh>
          </geometry>
          <material>
            <script>
              <name>Gazebo/Black</name>
              <uri>file://media/materials/scripts/gazebo.material</uri>
            </script>
          </material>
        </visual>
        <visual name='base_link_fixed_joint_lump__link_aruco_right_base_visual_3'>
          <pose>-0.001503 -0.130497 0.159748 0 0 -1.5708</pose>
          <geometry>
            <mesh>
              <scale>1 1 1</scale>
              <uri>/home/sandisk/koyo_ws/stretch_ws/src/stretch_ros/stretch_description/meshes/link_aruco_right_base.STL</uri>
            </mesh>
          </geometry>
          <material>
            <script>
              <name>Gazebo/Black</name>
              <uri>file://media/materials/scripts/gazebo.material</uri>
            </script>
          </material>
        </visual>
        <visual name='base_link_fixed_joint_lump__laser_visual_4'>
          <pose>0.004 0 0.1664 0 0 -3.14159</pose>
          <geometry>
            <mesh>
              <scale>1 1 1</scale>
              <uri>/home/sandisk/koyo_ws/stretch_ws/src/stretch_ros/stretch_description/meshes/laser.STL</uri>
            </mesh>
          </geometry>
          <material>
            <script>
              <name>Gazebo/Black</name>
              <uri>file://media/materials/scripts/gazebo.material</uri>
            </script>
          </material>
        </visual>
        <visual name='base_link_fixed_joint_lump__link_mast_visual_5'>
          <pose>-0.067 0.135 0.0284 1.5708 -0 0</pose>
          <geometry>
            <mesh>
              <scale>1 1 1</scale>
              <uri>/home/sandisk/koyo_ws/stretch_ws/src/stretch_ros/stretch_description/meshes/link_mast.STL</uri>
            </mesh>
          </geometry>
          <material>
            <script>
              <name>Gazebo/Gray</name>
              <uri>file://media/materials/scripts/gazebo.material</uri>
            </script>
          </material>
        </visual>
        <visual name='base_link_fixed_joint_lump__link_head_visual_6'>
          <pose>-0.067 0.134995 1.3584 7e-06 4e-06 -1.5708</pose>
          <geometry>
            <mesh>
              <scale>1 1 1</scale>
              <uri>/home/sandisk/koyo_ws/stretch_ws/src/stretch_ros/stretch_description/meshes/link_head.STL</uri>
            </mesh>
          </geometry>
          <material>
            <script>
              <name>Gazebo/Gray</name>
              <uri>file://media/materials/scripts/gazebo.material</uri>
            </script>
          </material>
        </visual>
        <visual name='base_link_fixed_joint_lump__respeaker_base_visual_7'>
          <pose>-0.067 0.131964 1.40076 3e-06 2e-06 -0.698132</pose>
          <geometry>
            <mesh>
              <scale>1 1 1</scale>
              <uri>/home/sandisk/koyo_ws/stretch_ws/src/stretch_ros/stretch_description/meshes/respeaker_base.STL</uri>
            </mesh>
          </geometry>
          <material>
            <script>
              <name>Gazebo/Green</name>
              <uri>file://media/materials/scripts/gazebo.material</uri>
            </script>
          </material>
        </visual>
        <sensor name='base_imu' type='imu'>
          <always_on>1</always_on>
          <visualize>0</visualize>
          <plugin name='imu_plugin' filename='libgazebo_ros_imu_sensor.so'>
            <topicName>imu/data</topicName>
            <bodyName>base_link</bodyName>
            <updateRateHZ>25.0</updateRateHZ>
            <gaussianNoise>0.001</gaussianNoise>
            <xyzOffset>0 0 0</xyzOffset>
            <rpyOffset>0 0 0</rpyOffset>
            <frameName>base_link</frameName>
            <initialOrientationAsReference>0</initialOrientationAsReference>
            <robotNamespace>/</robotNamespace>
          </plugin>
          <pose>0 0 0 0 -0 0</pose>
          <imu/>
        </sensor>
        <gravity>1</gravity>
        <sensor name='laser_sensor' type='ray'>
          <visualize>0</visualize>
          <update_rate>5.5</update_rate>
          <ray>
            <scan>
              <horizontal>
                <samples>2000</samples>
                <resolution>1</resolution>
                <min_angle>-0.9</min_angle>
                <max_angle>5</max_angle>
              </horizontal>
              <vertical>
                <samples>1</samples>
                <min_angle>0</min_angle>
                <max_angle>0</max_angle>
              </vertical>
            </scan>
            <range>
              <min>0.15</min>
              <max>12</max>
              <resolution>0.01</resolution>
            </range>
            <noise>
              <type>gaussian</type>
              <mean>0</mean>
              <stddev>0.001</stddev>
            </noise>
          </ray>
          <plugin name='gazebo_ros_lidar_controller' filename='libgazebo_ros_laser.so'>
            <topicName>scan</topicName>
            <frameName>laser</frameName>
            <robotNamespace>/</robotNamespace>
          </plugin>
          <pose>0.004 0 0.1664 0 -0 -3.14159</pose>
        </sensor>
        <self_collide>0</self_collide>
        <enable_wind>0</enable_wind>
        <kinematic>0</kinematic>
      </link>
      <joint name='joint_left_wheel' type='revolute'>
        <pose relative_to='base_link'>0 0.17035 0.0508 -1.5708 0 0</pose>
        <parent>base_link</parent>
        <child>link_left_wheel</child>
        <axis>
          <xyz>0 0 1</xyz>
          <limit>
            <lower>-1e+16</lower>
            <upper>1e+16</upper>
          </limit>
          <dynamics>
            <damping>21.75</damping>
            <friction>10.48</friction>
            <spring_reference>0</spring_reference>
            <spring_stiffness>0</spring_stiffness>
          </dynamics>
        </axis>
      </joint>
      <link name='link_left_wheel'>
        <pose relative_to='joint_left_wheel'>0 0 0 0 -0 0</pose>
        <inertial>
          <pose>-0 -0 -0.037544 0 -0 0</pose>
          <mass>0.0042721</mass>
          <inertia>
            <ixx>0.001</ixx>
            <ixy>0</ixy>
            <ixz>0</ixz>
            <iyy>0.001</iyy>
            <iyz>0</iyz>
            <izz>0.001</izz>
          </inertia>
        </inertial>
        <collision name='link_left_wheel_collision'>
          <pose>0 0 0 0 -0 0</pose>
          <geometry>
            <mesh>
              <scale>1 1 1</scale>
              <uri>/home/sandisk/koyo_ws/stretch_ws/src/stretch_ros/stretch_description/meshes/link_left_wheel.STL</uri>
            </mesh>
          </geometry>
          <surface>
            <contact>
              <ode>
                <kp>1e+07</kp>
                <kd>100</kd>
                <min_depth>0.001</min_depth>
              </ode>
            </contact>
            <friction>
              <ode>
                <mu>100</mu>
                <mu2>200</mu2>
              </ode>
              <torsional>
                <ode/>
              </torsional>
            </friction>
            <bounce/>
          </surface>
          <max_contacts>10</max_contacts>
        </collision>
        <visual name='link_left_wheel_visual'>
          <pose>0 0 0 0 -0 0</pose>
          <geometry>
            <mesh>
              <scale>1 1 1</scale>
              <uri>/home/sandisk/koyo_ws/stretch_ws/src/stretch_ros/stretch_description/meshes/link_left_wheel.STL</uri>
            </mesh>
          </geometry>
          <material>
            <script>
              <name>Gazebo/Blue</name>
              <uri>file://media/materials/scripts/gazebo.material</uri>
            </script>
          </material>
        </visual>
        <self_collide>0</self_collide>
        <enable_wind>0</enable_wind>
        <kinematic>0</kinematic>
      </link>
      <joint name='joint_head_pan' type='revolute'>
        <pose relative_to='base_link'>0.0061 -5e-06 1.3552 4e-06 -7e-06 -0</pose>
        <parent>base_link</parent>
        <child>link_head_pan</child>
        <axis>
          <xyz>0 0 1</xyz>
          <limit>
            <lower>-3.9</lower>
            <upper>1.5</upper>
            <effort>100</effort>
            <velocity>1</velocity>
          </limit>
          <dynamics>
            <spring_reference>0</spring_reference>
            <spring_stiffness>0</spring_stiffness>
          </dynamics>
        </axis>
      </joint>
      <link name='link_head_pan'>
        <pose relative_to='joint_head_pan'>0 0 0 0 -0 0</pose>
        <inertial>
          <pose>-0.000327 0.0085 0.00013 0 -0 0</pose>
          <mass>0.0273764</mass>
          <inertia>
            <ixx>0.001</ixx>
            <ixy>0</ixy>
            <ixz>0</ixz>
            <iyy>0.001</iyy>
            <iyz>0</iyz>
            <izz>0.001</izz>
          </inertia>
        </inertial>
        <collision name='link_head_pan_collision'>
          <pose>0 0 0 0 -0 0</pose>
          <geometry>
            <mesh>
              <scale>1 1 1</scale>
              <uri>/home/sandisk/koyo_ws/stretch_ws/src/stretch_ros/stretch_description/meshes/link_head_pan.STL</uri>
            </mesh>
          </geometry>
          <surface>
            <contact>
              <ode>
                <kp>1e+07</kp>
                <kd>100</kd>
                <min_depth>0.001</min_depth>
              </ode>
            </contact>
            <friction>
              <ode>
                <mu>100</mu>
                <mu2>200</mu2>
              </ode>
              <torsional>
                <ode/>
              </torsional>
            </friction>
            <bounce/>
          </surface>
          <max_contacts>10</max_contacts>
        </collision>
        <visual name='link_head_pan_visual'>
          <pose>0 0 0 0 -0 0</pose>
          <geometry>
            <mesh>
              <scale>1 1 1</scale>
              <uri>/home/sandisk/koyo_ws/stretch_ws/src/stretch_ros/stretch_description/meshes/link_head_pan.STL</uri>
            </mesh>
          </geometry>
          <material>
            <script>
              <name>Gazebo/Gray</name>
              <uri>file://media/materials/scripts/gazebo.material</uri>
            </script>
          </material>
        </visual>
        <self_collide>0</self_collide>
        <enable_wind>0</enable_wind>
        <kinematic>0</kinematic>
      </link>
      <joint name='joint_head_tilt' type='revolute'>
        <pose relative_to='link_head_pan'>-0.0013 0.027762 -0.053311 1.5708 -0 0</pose>
        <parent>link_head_pan</parent>
        <child>link_head_tilt</child>
        <axis>
          <xyz>0 0 1</xyz>
          <limit>
            <lower>-1.53</lower>
            <upper>0.79</upper>
            <effort>100</effort>
            <velocity>1</velocity>
          </limit>
          <dynamics>
            <spring_reference>0</spring_reference>
            <spring_stiffness>0</spring_stiffness>
          </dynamics>
        </axis>
      </joint>
      <link name='link_head_tilt'>
        <pose relative_to='joint_head_tilt'>0 0 0 0 -0 0</pose>
        <inertial>
          <pose>0.021939 -0.009452 0.030425 0 -0 0</pose>
          <mass>0.162217</mass>
          <inertia>
            <ixx>0.00490943</ixx>
            <ixy>-3.56401e-05</ixy>
            <ixz>-6.63879e-07</ixz>
            <iyy>0.00154403</iyy>
            <iyz>-5.24815e-07</iyz>
            <izz>0.00495252</izz>
          </inertia>
        </inertial>
        <collision name='link_head_tilt_collision'>
          <pose>0 0 0 0 -0 0</pose>
          <geometry>
            <mesh>
              <scale>1 1 1</scale>
              <uri>/home/sandisk/koyo_ws/stretch_ws/src/stretch_ros/stretch_description/meshes/link_head_tilt.STL</uri>
            </mesh>
          </geometry>
          <surface>
            <contact>
              <ode>
                <kp>1e+07</kp>
                <kd>100</kd>
                <min_depth>0.001</min_depth>
              </ode>
            </contact>
            <friction>
              <ode>
                <mu>100</mu>
                <mu2>200</mu2>
              </ode>
              <torsional>
                <ode/>
              </torsional>
            </friction>
            <bounce/>
          </surface>
          <max_contacts>10</max_contacts>
        </collision>
        <collision name='link_head_tilt_fixed_joint_lump__camera_link_collision_1'>
          <pose>0.0406 -0.0122 0.0307 0 -0 0</pose>
          <geometry>
            <box>
              <size>0.02505 0.09 0.025</size>
            </box>
          </geometry>
          <max_contacts>10</max_contacts>
          <surface>
            <contact>
              <ode/>
            </contact>
            <bounce/>
            <friction>
              <torsional>
                <ode/>
              </torsional>
              <ode/>
            </friction>
          </surface>
        </collision>
        <visual name='link_head_tilt_visual'>
          <pose>0 0 0 0 -0 0</pose>
          <geometry>
            <mesh>
              <scale>1 1 1</scale>
              <uri>/home/sandisk/koyo_ws/stretch_ws/src/stretch_ros/stretch_description/meshes/link_head_tilt.STL</uri>
            </mesh>
          </geometry>
          <material>
            <script>
              <name>Gazebo/Gray</name>
              <uri>file://media/materials/scripts/gazebo.material</uri>
            </script>
          </material>
        </visual>
        <visual name='link_head_tilt_fixed_joint_lump__camera_link_visual_1'>
          <pose>0.0449 -0.0122 0.0307 1.5708 -0 1.5708</pose>
          <geometry>
            <mesh>
              <scale>1 1 1</scale>
              <uri>/opt/ros/noetic/share/realsense2_description/meshes/d435.dae</uri>
            </mesh>
          </geometry>
        </visual>
        <sensor name='color' type='camera'>
          <camera name='__default__'>
            <horizontal_fov>1.50098</horizontal_fov>
            <image>
              <width>640</width>
              <height>480</height>
              <format>RGB_INT8</format>
            </image>
            <clip>
              <near>0.1</near>
              <far>100</far>
            </clip>
            <noise>
              <type>gaussian</type>
              <mean>0</mean>
              <stddev>0.007</stddev>
            </noise>
          </camera>
          <always_on>1</always_on>
          <update_rate>30</update_rate>
          <visualize>0</visualize>
          <pose>0.0406 0.0203 0.0307 0 -0 0</pose>
        </sensor>
        <sensor name='depth' type='depth'>
          <camera name='__default__'>
            <horizontal_fov>1.50098</horizontal_fov>
            <image>
              <width>640</width>
              <height>480</height>
            </image>
            <clip>
              <near>0.1</near>
              <far>100</far>
            </clip>
            <noise>
              <type>gaussian</type>
              <mean>0</mean>
              <stddev>0.007</stddev>
            </noise>
          </camera>
          <always_on>1</always_on>
          <update_rate>30</update_rate>
          <visualize>0</visualize>
          <pose>0.0406 0.0053 0.0307 0 -0 0</pose>
        </sensor>
        <gravity>1</gravity>
        <sensor name='imu_sensor' type='imu'>
          <always_on>1</always_on>
          <visualize>0</visualize>
          <plugin name='imu_plugin' filename='libgazebo_ros_imu_sensor.so'>
            <topicName>camera/imu/data</topicName>
            <bodyName>camera_gyro_frame</bodyName>
            <updateRateHZ>50.0</updateRateHZ>
            <gaussianNoise>0.001</gaussianNoise>
            <xyzOffset>0 0 0</xyzOffset>
            <rpyOffset>0 0 0</rpyOffset>
            <frameName>camera_gyro_frame</frameName>
            <initialOrientationAsReference>0</initialOrientationAsReference>
            <robotNamespace>/</robotNamespace>
          </plugin>
          <pose>0.02886 -0.00022 0.0358 0 -0 0</pose>
          <imu/>
        </sensor>
        <sensor name='ired1' type='camera'>
          <camera name='__default__'>
            <horizontal_fov>1.50098</horizontal_fov>
            <image>
              <width>640</width>
              <height>480</height>
              <format>L_INT8</format>
            </image>
            <clip>
              <near>0.1</near>
              <far>100</far>
            </clip>
            <noise>
              <type>gaussian</type>
              <mean>0</mean>
              <stddev>0.007</stddev>
            </noise>
          </camera>
          <always_on>1</always_on>
          <update_rate>30</update_rate>
          <visualize>0</visualize>
          <pose>0.0406 0.0053 0.0307 0 -0 0</pose>
        </sensor>
        <sensor name='ired2' type='camera'>
          <camera name='__default__'>
            <horizontal_fov>1.50098</horizontal_fov>
            <image>
              <width>640</width>
              <height>480</height>
              <format>L_INT8</format>
            </image>
            <clip>
              <near>0.1</near>
              <far>100</far>
            </clip>
            <noise>
              <type>gaussian</type>
              <mean>0</mean>
              <stddev>0.007</stddev>
            </noise>
          </camera>
          <always_on>1</always_on>
          <update_rate>30</update_rate>
          <visualize>0</visualize>
          <pose>0.0406 -0.0447 0.0307 0 -0 0</pose>
        </sensor>
        <self_collide>0</self_collide>
        <enable_wind>0</enable_wind>
        <kinematic>0</kinematic>
      </link>
      <joint name='joint_lift' type='prismatic'>
        <pose relative_to='base_link'>-0.104385 0.134999 0.195 -4e-06 -4e-06 1.5708</pose>
        <parent>base_link</parent>
        <child>link_lift</child>
        <axis>
          <xyz>0 0 1</xyz>
          <limit>
            <lower>0</lower>
            <upper>1.1</upper>
            <effort>100</effort>
            <velocity>1</velocity>
          </limit>
          <dynamics>
            <spring_reference>0</spring_reference>
            <spring_stiffness>0</spring_stiffness>
          </dynamics>
        </axis>
      </joint>
      <link name='link_lift'>
        <pose relative_to='joint_lift'>0 0 0 0 -0 0</pose>
        <inertial>
          <pose>-0.057389 0.030718 0.010683 0 -0 0</pose>
          <mass>0.340275</mass>
          <inertia>
            <ixx>0.000615788</ixx>
            <ixy>-0.000119232</ixy>
            <ixz>-0.000112834</ixz>
            <iyy>0.00133783</iyy>
            <iyz>-3.42328e-05</iyz>
            <izz>0.00147485</izz>
          </inertia>
        </inertial>
        <collision name='link_lift_collision'>
          <pose>0 0 0 0 -0 0</pose>
          <geometry>
            <mesh>
              <scale>1 1 1</scale>
              <uri>/home/sandisk/koyo_ws/stretch_ws/src/stretch_ros/stretch_description/meshes/link_lift.STL</uri>
            </mesh>
          </geometry>
          <surface>
            <contact>
              <ode>
                <kp>1e+07</kp>
                <kd>100</kd>
                <min_depth>0.001</min_depth>
              </ode>
            </contact>
            <friction>
              <ode>
                <mu>10000</mu>
                <mu2>10000</mu2>
              </ode>
              <torsional>
                <ode/>
              </torsional>
            </friction>
            <bounce/>
          </surface>
          <max_contacts>10</max_contacts>
        </collision>
        <collision name='link_lift_fixed_joint_lump__link_arm_l4_collision_1'>
          <pose>-0.2547 0 0 1.5708 0 -1.5708</pose>
          <geometry>
            <mesh>
              <scale>1 1 1</scale>
              <uri>/home/sandisk/koyo_ws/stretch_ws/src/stretch_ros/stretch_description/meshes/link_arm_l4.STL</uri>
            </mesh>
          </geometry>
          <surface>
            <contact>
              <ode>
                <kp>1e+07</kp>
                <kd>100</kd>
                <min_depth>0.001</min_depth>
              </ode>
            </contact>
            <friction>
              <ode>
                <mu>100</mu>
                <mu2>200</mu2>
              </ode>
              <torsional>
                <ode/>
              </torsional>
            </friction>
            <bounce/>
          </surface>
          <max_contacts>10</max_contacts>
        </collision>
        <collision name='link_lift_fixed_joint_lump__link_aruco_shoulder_collision_2'>
          <pose>-0.013377 0.055854 0.086137 0 -0 0</pose>
          <geometry>
            <mesh>
              <scale>1 1 1</scale>
              <uri>/home/sandisk/koyo_ws/stretch_ws/src/stretch_ros/stretch_description/meshes/link_aruco_shoulder.STL</uri>
            </mesh>
          </geometry>
          <surface>
            <contact>
              <ode/>
            </contact>
            <friction>
              <ode/>
              <torsional>
                <ode/>
              </torsional>
            </friction>
            <bounce/>
          </surface>
          <max_contacts>10</max_contacts>
        </collision>
        <visual name='link_lift_visual'>
          <pose>0 0 0 0 -0 0</pose>
          <geometry>
            <mesh>
              <scale>1 1 1</scale>
              <uri>/home/sandisk/koyo_ws/stretch_ws/src/stretch_ros/stretch_description/meshes/link_lift.STL</uri>
            </mesh>
          </geometry>
          <material>
            <script>
              <name>Gazebo/Black</name>
              <uri>file://media/materials/scripts/gazebo.material</uri>
            </script>
          </material>
        </visual>
        <visual name='link_lift_fixed_joint_lump__link_arm_l4_visual_1'>
          <pose>-0.2547 0 0 1.5708 0 -1.5708</pose>
          <geometry>
            <mesh>
              <scale>1 1 1</scale>
              <uri>/home/sandisk/koyo_ws/stretch_ws/src/stretch_ros/stretch_description/meshes/link_arm_l4.STL</uri>
            </mesh>
          </geometry>
          <material>
            <script>
              <name>Gazebo/Gray</name>
              <uri>file://media/materials/scripts/gazebo.material</uri>
            </script>
          </material>
        </visual>
        <visual name='link_lift_fixed_joint_lump__link_aruco_shoulder_visual_2'>
          <pose>-0.013377 0.055854 0.086137 0 -0 0</pose>
          <geometry>
            <mesh>
              <scale>1 1 1</scale>
              <uri>/home/sandisk/koyo_ws/stretch_ws/src/stretch_ros/stretch_description/meshes/link_aruco_shoulder.STL</uri>
            </mesh>
          </geometry>
          <material>
            <script>
              <name>Gazebo/Black</name>
              <uri>file://media/materials/scripts/gazebo.material</uri>
            </script>
          </material>
        </visual>
        <self_collide>0</self_collide>
        <enable_wind>0</enable_wind>
        <kinematic>0</kinematic>
      </link>
      <joint name='joint_arm_l3' type='prismatic'>
        <pose relative_to='link_lift'>-0.2677 0 -0 1.5708 0 -1.5708</pose>
        <parent>link_lift</parent>
        <child>link_arm_l3</child>
        <axis>
          <xyz>0 0 1</xyz>
          <limit>
            <lower>0</lower>
            <upper>0.13</upper>
            <effort>100</effort>
            <velocity>1</velocity>
          </limit>
          <dynamics>
            <spring_reference>0</spring_reference>
            <spring_stiffness>0</spring_stiffness>
          </dynamics>
        </axis>
      </joint>
      <link name='link_arm_l3'>
        <pose relative_to='joint_arm_l3'>0 0 0 0 -0 0</pose>
        <inertial>
          <pose>-1e-06 -2e-05 -0.09711 0 -0 0</pose>
          <mass>0.0628927</mass>
          <inertia>
            <ixx>0.001</ixx>
            <ixy>0</ixy>
            <ixz>0</ixz>
            <iyy>0.001</iyy>
            <iyz>0</iyz>
            <izz>0.001</izz>
          </inertia>
        </inertial>
        <collision name='link_arm_l3_collision'>
          <pose>0 0 0 0 -0 0</pose>
          <geometry>
            <mesh>
              <scale>1 1 1</scale>
              <uri>/home/sandisk/koyo_ws/stretch_ws/src/stretch_ros/stretch_description/meshes/link_arm_l3.STL</uri>
            </mesh>
          </geometry>
          <surface>
            <contact>
              <ode>
                <kp>1e+07</kp>
                <kd>100</kd>
                <min_depth>0.001</min_depth>
              </ode>
            </contact>
            <friction>
              <ode>
                <mu>100</mu>
                <mu2>200</mu2>
              </ode>
              <torsional>
                <ode/>
              </torsional>
            </friction>
            <bounce/>
          </surface>
          <max_contacts>10</max_contacts>
        </collision>
        <visual name='link_arm_l3_visual'>
          <pose>0 0 0 0 -0 0</pose>
          <geometry>
            <mesh>
              <scale>1 1 1</scale>
              <uri>/home/sandisk/koyo_ws/stretch_ws/src/stretch_ros/stretch_description/meshes/link_arm_l3.STL</uri>
            </mesh>
          </geometry>
          <material>
            <script>
              <name>Gazebo/Gray</name>
              <uri>file://media/materials/scripts/gazebo.material</uri>
            </script>
          </material>
        </visual>
        <self_collide>0</self_collide>
        <enable_wind>0</enable_wind>
        <kinematic>0</kinematic>
      </link>
      <joint name='joint_arm_l2' type='prismatic'>
        <pose relative_to='link_arm_l3'>0 0 0.013 0 -0 0</pose>
        <parent>link_arm_l3</parent>
        <child>link_arm_l2</child>
        <axis>
          <xyz>0 0 1</xyz>
          <limit>
            <lower>0</lower>
            <upper>0.13</upper>
            <effort>100</effort>
            <velocity>1</velocity>
          </limit>
          <dynamics>
            <spring_reference>0</spring_reference>
            <spring_stiffness>0</spring_stiffness>
          </dynamics>
        </axis>
      </joint>
      <link name='link_arm_l2'>
        <pose relative_to='joint_arm_l2'>0 0 0 0 -0 0</pose>
        <inertial>
          <pose>-1e-06 -2e-05 -0.096882 0 -0 0</pose>
          <mass>0.0571386</mass>
          <inertia>
            <ixx>0.001</ixx>
            <ixy>0</ixy>
            <ixz>0</ixz>
            <iyy>0.001</iyy>
            <iyz>0</iyz>
            <izz>0.001</izz>
          </inertia>
        </inertial>
        <collision name='link_arm_l2_collision'>
          <pose>0 0 0 0 -0 0</pose>
          <geometry>
            <mesh>
              <scale>1 1 1</scale>
              <uri>/home/sandisk/koyo_ws/stretch_ws/src/stretch_ros/stretch_description/meshes/link_arm_l2.STL</uri>
            </mesh>
          </geometry>
          <surface>
            <contact>
              <ode>
                <kp>1e+07</kp>
                <kd>100</kd>
                <min_depth>0.001</min_depth>
              </ode>
            </contact>
            <friction>
              <ode>
                <mu>100</mu>
                <mu2>200</mu2>
              </ode>
              <torsional>
                <ode/>
              </torsional>
            </friction>
            <bounce/>
          </surface>
          <max_contacts>10</max_contacts>
        </collision>
        <visual name='link_arm_l2_visual'>
          <pose>0 0 0 0 -0 0</pose>
          <geometry>
            <mesh>
              <scale>1 1 1</scale>
              <uri>/home/sandisk/koyo_ws/stretch_ws/src/stretch_ros/stretch_description/meshes/link_arm_l2.STL</uri>
            </mesh>
          </geometry>
          <material>
            <script>
              <name>Gazebo/Gray</name>
              <uri>file://media/materials/scripts/gazebo.material</uri>
            </script>
          </material>
        </visual>
        <self_collide>0</self_collide>
        <enable_wind>0</enable_wind>
        <kinematic>0</kinematic>
      </link>
      <joint name='joint_arm_l1' type='prismatic'>
        <pose relative_to='link_arm_l2'>0 0 0.013 0 -0 0</pose>
        <parent>link_arm_l2</parent>
        <child>link_arm_l1</child>
        <axis>
          <xyz>0 0 1</xyz>
          <limit>
            <lower>0</lower>
            <upper>0.13</upper>
            <effort>100</effort>
            <velocity>1</velocity>
          </limit>
          <dynamics>
            <spring_reference>0</spring_reference>
            <spring_stiffness>0</spring_stiffness>
          </dynamics>
        </axis>
      </joint>
      <link name='link_arm_l1'>
        <pose relative_to='joint_arm_l1'>0 0 0 0 -0 0</pose>
        <inertial>
          <pose>-1e-06 -2e-05 -0.096543 0 -0 0</pose>
          <mass>0.051382</mass>
          <inertia>
            <ixx>0.001</ixx>
            <ixy>0</ixy>
            <ixz>0</ixz>
            <iyy>0.001</iyy>
            <iyz>0</iyz>
            <izz>0.001</izz>
          </inertia>
        </inertial>
        <collision name='link_arm_l1_collision'>
          <pose>0 0 0 0 -0 0</pose>
          <geometry>
            <mesh>
              <scale>1 1 1</scale>
              <uri>/home/sandisk/koyo_ws/stretch_ws/src/stretch_ros/stretch_description/meshes/link_arm_l1.STL</uri>
            </mesh>
          </geometry>
          <surface>
            <contact>
              <ode>
                <kp>1e+07</kp>
                <kd>100</kd>
                <min_depth>0.001</min_depth>
              </ode>
            </contact>
            <friction>
              <ode>
                <mu>100</mu>
                <mu2>200</mu2>
              </ode>
              <torsional>
                <ode/>
              </torsional>
            </friction>
            <bounce/>
          </surface>
          <max_contacts>10</max_contacts>
        </collision>
        <visual name='link_arm_l1_visual'>
          <pose>0 0 0 0 -0 0</pose>
          <geometry>
            <mesh>
              <scale>1 1 1</scale>
              <uri>/home/sandisk/koyo_ws/stretch_ws/src/stretch_ros/stretch_description/meshes/link_arm_l1.STL</uri>
            </mesh>
          </geometry>
          <material>
            <script>
              <name>Gazebo/Gray</name>
              <uri>file://media/materials/scripts/gazebo.material</uri>
            </script>
          </material>
        </visual>
        <self_collide>0</self_collide>
        <enable_wind>0</enable_wind>
        <kinematic>0</kinematic>
      </link>
      <joint name='joint_arm_l0' type='prismatic'>
        <pose relative_to='link_arm_l1'>0 0 -0.01375 0 -0 0</pose>
        <parent>link_arm_l1</parent>
        <child>link_arm_l0</child>
        <axis>
          <xyz>0 0 1</xyz>
          <limit>
            <lower>0</lower>
            <upper>0.13</upper>
            <effort>100</effort>
            <velocity>1</velocity>
          </limit>
          <dynamics>
            <spring_reference>0</spring_reference>
            <spring_stiffness>0</spring_stiffness>
          </dynamics>
        </axis>
      </joint>
      <link name='link_arm_l0'>
        <pose relative_to='joint_arm_l0'>0 0 0 0 -0 0</pose>
        <inertial>
          <pose>0.027058 -0.001899 -0.037781 0 -0 0</pose>
          <mass>0.0850033</mass>
          <inertia>
            <ixx>0.001</ixx>
            <ixy>0</ixy>
            <ixz>0</ixz>
            <iyy>0.001</iyy>
            <iyz>0</iyz>
            <izz>0.001</izz>
          </inertia>
        </inertial>
        <collision name='link_arm_l0_collision'>
          <pose>0 0 0 0 -0 0</pose>
          <geometry>
            <mesh>
              <scale>1 1 1</scale>
              <uri>/home/sandisk/koyo_ws/stretch_ws/src/stretch_ros/stretch_description/meshes/link_arm_l0.STL</uri>
            </mesh>
          </geometry>
          <surface>
            <contact>
              <ode>
                <kp>1e+07</kp>
                <kd>100</kd>
                <min_depth>0.001</min_depth>
              </ode>
            </contact>
            <friction>
              <ode>
                <mu>100</mu>
                <mu2>200</mu2>
              </ode>
              <torsional>
                <ode/>
              </torsional>
            </friction>
            <bounce/>
          </surface>
          <max_contacts>10</max_contacts>
        </collision>
        <collision name='link_arm_l0_fixed_joint_lump__link_aruco_inner_wrist_collision_1'>
          <pose>0.04725 -0.0119 -0.02725 3.14159 -0 3.14159</pose>
          <geometry>
            <mesh>
              <scale>1 1 1</scale>
              <uri>/home/sandisk/koyo_ws/stretch_ws/src/stretch_ros/stretch_description/meshes/link_aruco_inner_wrist.STL</uri>
            </mesh>
          </geometry>
          <surface>
            <contact>
              <ode/>
            </contact>
            <friction>
              <ode/>
              <torsional>
                <ode/>
              </torsional>
            </friction>
            <bounce/>
          </surface>
          <max_contacts>10</max_contacts>
        </collision>
        <collision name='link_arm_l0_fixed_joint_lump__link_aruco_top_wrist_collision_2'>
          <pose>0.04725 0.029285 0 1.5708 -0 3.14159</pose>
          <geometry>
            <mesh>
              <scale>1 1 1</scale>
              <uri>/home/sandisk/koyo_ws/stretch_ws/src/stretch_ros/stretch_description/meshes/link_aruco_top_wrist.STL</uri>
            </mesh>
          </geometry>
          <surface>
            <contact>
              <ode/>
            </contact>
            <friction>
              <ode/>
              <torsional>
                <ode/>
              </torsional>
            </friction>
            <bounce/>
          </surface>
          <max_contacts>10</max_contacts>
        </collision>
        <visual name='link_arm_l0_visual'>
          <pose>0 0 0 0 -0 0</pose>
          <geometry>
            <mesh>
              <scale>1 1 1</scale>
              <uri>/home/sandisk/koyo_ws/stretch_ws/src/stretch_ros/stretch_description/meshes/link_arm_l0.STL</uri>
            </mesh>
          </geometry>
          <material>
            <script>
              <name>Gazebo/Gray</name>
              <uri>file://media/materials/scripts/gazebo.material</uri>
            </script>
          </material>
        </visual>
        <visual name='link_arm_l0_fixed_joint_lump__link_aruco_inner_wrist_visual_1'>
          <pose>0.04725 -0.0119 -0.02725 3.14159 -0 3.14159</pose>
          <geometry>
            <mesh>
              <scale>1 1 1</scale>
              <uri>/home/sandisk/koyo_ws/stretch_ws/src/stretch_ros/stretch_description/meshes/link_aruco_inner_wrist.STL</uri>
            </mesh>
          </geometry>
          <material>
            <script>
              <name>Gazebo/Black</name>
              <uri>file://media/materials/scripts/gazebo.material</uri>
            </script>
          </material>
        </visual>
        <visual name='link_arm_l0_fixed_joint_lump__link_aruco_top_wrist_visual_2'>
          <pose>0.04725 0.029285 0 1.5708 -0 3.14159</pose>
          <geometry>
            <mesh>
              <scale>1 1 1</scale>
              <uri>/home/sandisk/koyo_ws/stretch_ws/src/stretch_ros/stretch_description/meshes/link_aruco_top_wrist.STL</uri>
            </mesh>
          </geometry>
          <material>
            <script>
              <name>Gazebo/Black</name>
              <uri>file://media/materials/scripts/gazebo.material</uri>
            </script>
          </material>
        </visual>
        <self_collide>0</self_collide>
        <enable_wind>0</enable_wind>
        <kinematic>0</kinematic>
      </link>
      <joint name='joint_wrist_yaw' type='revolute'>
        <pose relative_to='link_arm_l0'>0.083 -0.03075 0 1.5708 -0 0</pose>
        <parent>link_arm_l0</parent>
        <child>link_wrist_yaw</child>
        <axis>
          <xyz>0 0 -1</xyz>
          <limit>
            <lower>-1.75</lower>
            <upper>4</upper>
            <effort>100</effort>
            <velocity>1</velocity>
          </limit>
          <dynamics>
            <spring_reference>0</spring_reference>
            <spring_stiffness>0</spring_stiffness>
          </dynamics>
        </axis>
      </joint>
      <link name='link_wrist_yaw'>
        <pose relative_to='joint_wrist_yaw'>0 0 0 0 -0 0</pose>
        <inertial>
          <pose>-0.009405 0.012192 0.021206 0 -0 0</pose>
          <mass>0.142377</mass>
          <inertia>
            <ixx>0.00209963</ixx>
            <ixy>6.46903e-06</ixy>
            <ixz>2.13665e-05</ixz>
            <iyy>0.00209626</iyy>
            <iyz>-2.76309e-05</iyz>
            <izz>0.00201337</izz>
          </inertia>
        </inertial>
        <collision name='link_wrist_yaw_collision'>
          <pose>0 0 0 0 -0 0</pose>
          <geometry>
            <mesh>
              <scale>1 1 1</scale>
              <uri>/home/sandisk/koyo_ws/stretch_ws/src/stretch_ros/stretch_description/meshes/link_wrist_yaw.STL</uri>
            </mesh>
          </geometry>
          <surface>
            <contact>
              <ode>
                <kp>1e+07</kp>
                <kd>100</kd>
                <min_depth>0.001</min_depth>
              </ode>
            </contact>
            <friction>
              <ode>
                <mu>100</mu>
                <mu2>200</mu2>
              </ode>
              <torsional>
                <ode/>
              </torsional>
            </friction>
            <bounce/>
          </surface>
          <max_contacts>10</max_contacts>
        </collision>
        <collision name='link_wrist_yaw_fixed_joint_lump__link_gripper_collision_1'>
          <pose>0 0 0 3.14159 -0 -1.5708</pose>
          <geometry>
            <mesh>
              <scale>1 1 1</scale>
              <uri>/home/sandisk/koyo_ws/stretch_ws/src/stretch_ros/stretch_description/meshes/link_gripper.STL</uri>
            </mesh>
          </geometry>
          <surface>
            <contact>
              <ode>
                <kp>1e+07</kp>
                <kd>100</kd>
                <min_depth>0.001</min_depth>
              </ode>
            </contact>
            <friction>
              <ode>
                <mu>100</mu>
                <mu2>200</mu2>
              </ode>
              <torsional>
                <ode/>
              </torsional>
            </friction>
            <bounce/>
          </surface>
          <max_contacts>10</max_contacts>
        </collision>
        <visual name='link_wrist_yaw_visual'>
          <pose>0 0 0 0 -0 0</pose>
          <geometry>
            <mesh>
              <scale>1 1 1</scale>
              <uri>/home/sandisk/koyo_ws/stretch_ws/src/stretch_ros/stretch_description/meshes/link_wrist_yaw.STL</uri>
            </mesh>
          </geometry>
          <material>
            <script>
              <name>Gazebo/Black</name>
              <uri>file://media/materials/scripts/gazebo.material</uri>
            </script>
          </material>
        </visual>
        <visual name='link_wrist_yaw_fixed_joint_lump__link_gripper_visual_1'>
          <pose>0 0 0 3.14159 -0 -1.5708</pose>
          <geometry>
            <mesh>
              <scale>1 1 1</scale>
              <uri>/home/sandisk/koyo_ws/stretch_ws/src/stretch_ros/stretch_description/meshes/link_gripper.STL</uri>
            </mesh>
          </geometry>
          <material>
            <script>
              <name>Gazebo/Gray</name>
              <uri>file://media/materials/scripts/gazebo.material</uri>
            </script>
          </material>
        </visual>
        <gravity>1</gravity>
        <sensor name='wrist_imu' type='imu'>
          <always_on>1</always_on>
          <visualize>0</visualize>
          <plugin name='imu_plugin' filename='libgazebo_ros_imu_sensor.so'>
            <topicName>wrist_imu/data</topicName>
            <bodyName>link_wrist_yaw</bodyName>
            <updateRateHZ>25.0</updateRateHZ>
            <gaussianNoise>0.001</gaussianNoise>
            <xyzOffset>0 0 0</xyzOffset>
            <rpyOffset>0 0 0</rpyOffset>
            <frameName>link_wrist_yaw</frameName>
            <initialOrientationAsReference>0</initialOrientationAsReference>
            <robotNamespace>/</robotNamespace>
          </plugin>
          <pose>0 0 0 0 -0 0</pose>
          <imu/>
        </sensor>
        <self_collide>0</self_collide>
        <enable_wind>0</enable_wind>
        <kinematic>0</kinematic>
      </link>
      <joint name='joint_gripper_finger_left' type='revolute'>
        <pose relative_to='link_wrist_yaw'>0.010151 0.047231 0.04679 -3.14159 -0.5236 1.57078</pose>
        <parent>link_wrist_yaw</parent>
        <child>link_gripper_finger_left</child>
        <axis>
          <xyz>0 0 1</xyz>
          <limit>
            <lower>-0.6</lower>
            <upper>0.6</upper>
            <effort>100</effort>
            <velocity>1</velocity>
          </limit>
          <dynamics>
            <spring_reference>0</spring_reference>
            <spring_stiffness>0</spring_stiffness>
          </dynamics>
        </axis>
      </joint>
      <link name='link_gripper_finger_left'>
        <pose relative_to='joint_gripper_finger_left'>0 0 0 0 -0 0</pose>
        <inertial>
          <pose>0.100529 0.012112 -0 0 -0 0</pose>
          <mass>0.0514424</mass>
          <inertia>
            <ixx>0.00200006</ixx>
            <ixy>1.22883e-06</ixy>
            <ixz>7.72702e-12</ixz>
            <iyy>0.00202327</iyy>
            <iyz>-4.08122e-13</iyz>
            <izz>0.00202333</izz>
          </inertia>
        </inertial>
        <collision name='link_gripper_finger_left_collision'>
          <pose>0 0 0 0 -0 0</pose>
          <geometry>
            <mesh>
              <scale>0.9 1 1</scale>
              <uri>/home/sandisk/koyo_ws/stretch_ws/src/stretch_ros/stretch_description/meshes/link_gripper_finger_left.STL</uri>
            </mesh>
          </geometry>
          <surface>
            <contact>
              <ode>
                <kp>1e+07</kp>
                <kd>100</kd>
                <min_depth>0.001</min_depth>
              </ode>
            </contact>
            <friction>
              <ode>
                <mu>100</mu>
                <mu2>200</mu2>
              </ode>
              <torsional>
                <ode/>
              </torsional>
            </friction>
            <bounce/>
          </surface>
          <max_contacts>10</max_contacts>
        </collision>
        <collision name='link_gripper_finger_left_fixed_joint_lump__link_gripper_fingertip_left_collision_1'>
          <pose>0.171099 0.014912 0 -1.5708 -0 -2.5545</pose>
          <geometry>
            <mesh>
              <scale>1 1 1</scale>
              <uri>/home/sandisk/koyo_ws/stretch_ws/src/stretch_ros/stretch_description/meshes/link_gripper_fingertip_left.STL</uri>
            </mesh>
          </geometry>
          <surface>
            <contact>
              <ode>
                <kp>1e+07</kp>
                <kd>100</kd>
                <min_depth>0.001</min_depth>
              </ode>
            </contact>
            <friction>
              <ode>
                <mu>100</mu>
                <mu2>200</mu2>
              </ode>
              <torsional>
                <ode/>
              </torsional>
            </friction>
            <bounce/>
          </surface>
          <max_contacts>10</max_contacts>
        </collision>
        <visual name='link_gripper_finger_left_visual'>
          <pose>0 0 0 0 -0 0</pose>
          <geometry>
            <mesh>
              <scale>0.9 1 1</scale>
              <uri>/home/sandisk/koyo_ws/stretch_ws/src/stretch_ros/stretch_description/meshes/link_gripper_finger_left.STL</uri>
            </mesh>
          </geometry>
          <material>
            <script>
              <name>Gazebo/Gray</name>
              <uri>file://media/materials/scripts/gazebo.material</uri>
            </script>
          </material>
        </visual>
        <visual name='link_gripper_finger_left_fixed_joint_lump__link_gripper_fingertip_left_visual_1'>
          <pose>0.171099 0.014912 0 -1.5708 -0 -2.5545</pose>
          <geometry>
            <mesh>
              <scale>1 1 1</scale>
              <uri>/home/sandisk/koyo_ws/stretch_ws/src/stretch_ros/stretch_description/meshes/link_gripper_fingertip_left.STL</uri>
            </mesh>
          </geometry>
          <material>
            <script>
              <name>Gazebo/Black</name>
              <uri>file://media/materials/scripts/gazebo.material</uri>
            </script>
          </material>
        </visual>
        <self_collide>0</self_collide>
        <enable_wind>0</enable_wind>
        <kinematic>0</kinematic>
      </link>
      <joint name='joint_gripper_finger_right' type='revolute'>
        <pose relative_to='link_wrist_yaw'>-0.010049 0.047231 0.04679 4e-06 0.5236 -1.5708</pose>
        <parent>link_wrist_yaw</parent>
        <child>link_gripper_finger_right</child>
        <axis>
          <xyz>0 0 1</xyz>
          <limit>
            <lower>-0.6</lower>
            <upper>0.6</upper>
            <effort>100</effort>
            <velocity>1</velocity>
          </limit>
          <dynamics>
            <spring_reference>0</spring_reference>
            <spring_stiffness>0</spring_stiffness>
          </dynamics>
        </axis>
      </joint>
      <link name='link_gripper_finger_right'>
        <pose relative_to='joint_gripper_finger_right'>0 0 0 0 -0 0</pose>
        <inertial>
          <pose>-0.100529 -0.012112 -0 0 -0 0</pose>
          <mass>0.0514424</mass>
          <inertia>
            <ixx>0.00200006</ixx>
            <ixy>1.22889e-06</ixy>
            <ixz>-1.04879e-11</ixz>
            <iyy>0.00202327</iyy>
            <iyz>5.53976e-13</iyz>
            <izz>0.00202333</izz>
          </inertia>
        </inertial>
        <collision name='link_gripper_finger_right_collision'>
          <pose>0 0 0 0 -0 0</pose>
          <geometry>
            <mesh>
              <scale>0.9 1 1</scale>
              <uri>/home/sandisk/koyo_ws/stretch_ws/src/stretch_ros/stretch_description/meshes/link_gripper_finger_right.STL</uri>
            </mesh>
          </geometry>
          <surface>
            <contact>
              <ode>
                <kp>1e+07</kp>
                <kd>100</kd>
                <min_depth>0.001</min_depth>
              </ode>
            </contact>
            <friction>
              <ode>
                <mu>100</mu>
                <mu2>200</mu2>
              </ode>
              <torsional>
                <ode/>
              </torsional>
            </friction>
            <bounce/>
          </surface>
          <max_contacts>10</max_contacts>
        </collision>
        <collision name='link_gripper_finger_right_fixed_joint_lump__link_gripper_fingertip_right_collision_1'>
          <pose>-0.171099 -0.014912 0 -1.5708 -0 0.58705</pose>
          <geometry>
            <mesh>
              <scale>1 1 1</scale>
              <uri>/home/sandisk/koyo_ws/stretch_ws/src/stretch_ros/stretch_description/meshes/link_gripper_fingertip_right.STL</uri>
            </mesh>
          </geometry>
          <surface>
            <contact>
              <ode>
                <kp>1e+07</kp>
                <kd>100</kd>
                <min_depth>0.001</min_depth>
              </ode>
            </contact>
            <friction>
              <ode>
                <mu>100</mu>
                <mu2>200</mu2>
              </ode>
              <torsional>
                <ode/>
              </torsional>
            </friction>
            <bounce/>
          </surface>
          <max_contacts>10</max_contacts>
        </collision>
        <visual name='link_gripper_finger_right_visual'>
          <pose>0 0 0 0 -0 0</pose>
          <geometry>
            <mesh>
              <scale>0.9 1 1</scale>
              <uri>/home/sandisk/koyo_ws/stretch_ws/src/stretch_ros/stretch_description/meshes/link_gripper_finger_right.STL</uri>
            </mesh>
          </geometry>
          <material>
            <script>
              <name>Gazebo/Gray</name>
              <uri>file://media/materials/scripts/gazebo.material</uri>
            </script>
          </material>
        </visual>
        <visual name='link_gripper_finger_right_fixed_joint_lump__link_gripper_fingertip_right_visual_1'>
          <pose>-0.171099 -0.014912 0 -1.5708 -0 0.58705</pose>
          <geometry>
            <mesh>
              <scale>1 1 1</scale>
              <uri>/home/sandisk/koyo_ws/stretch_ws/src/stretch_ros/stretch_description/meshes/link_gripper_fingertip_right.STL</uri>
            </mesh>
          </geometry>
          <material>
            <script>
              <name>Gazebo/Black</name>
              <uri>file://media/materials/scripts/gazebo.material</uri>
            </script>
          </material>
        </visual>
        <self_collide>0</self_collide>
        <enable_wind>0</enable_wind>
        <kinematic>0</kinematic>
      </link>
      <joint name='joint_right_wheel' type='revolute'>
        <pose relative_to='base_link'>0 -0.17035 0.0508 -1.5708 0 0</pose>
        <parent>base_link</parent>
        <child>link_right_wheel</child>
        <axis>
          <xyz>0 0 1</xyz>
          <limit>
            <lower>-1e+16</lower>
            <upper>1e+16</upper>
          </limit>
          <dynamics>
            <damping>21.75</damping>
            <friction>10.48</friction>
            <spring_reference>0</spring_reference>
            <spring_stiffness>0</spring_stiffness>
          </dynamics>
        </axis>
      </joint>
      <link name='link_right_wheel'>
        <pose relative_to='joint_right_wheel'>0 0 0 0 -0 0</pose>
        <inertial>
          <pose>0 0 0.037544 0 -0 0</pose>
          <mass>0.0042721</mass>
          <inertia>
            <ixx>0.001</ixx>
            <ixy>0</ixy>
            <ixz>0</ixz>
            <iyy>0.001</iyy>
            <iyz>0</iyz>
            <izz>0.001</izz>
          </inertia>
        </inertial>
        <collision name='link_right_wheel_collision'>
          <pose>0 0 0 0 -0 0</pose>
          <geometry>
            <mesh>
              <scale>1 1 1</scale>
              <uri>/home/sandisk/koyo_ws/stretch_ws/src/stretch_ros/stretch_description/meshes/link_right_wheel.STL</uri>
            </mesh>
          </geometry>
          <surface>
            <contact>
              <ode>
                <kp>1e+07</kp>
                <kd>100</kd>
                <min_depth>0.001</min_depth>
              </ode>
            </contact>
            <friction>
              <ode>
                <mu>100</mu>
                <mu2>200</mu2>
              </ode>
              <torsional>
                <ode/>
              </torsional>
            </friction>
            <bounce/>
          </surface>
          <max_contacts>10</max_contacts>
        </collision>
        <visual name='link_right_wheel_visual'>
          <pose>0 0 0 0 -0 0</pose>
          <geometry>
            <mesh>
              <scale>1 1 1</scale>
              <uri>/home/sandisk/koyo_ws/stretch_ws/src/stretch_ros/stretch_description/meshes/link_right_wheel.STL</uri>
            </mesh>
          </geometry>
          <material>
            <script>
              <name>Gazebo/Blue</name>
              <uri>file://media/materials/scripts/gazebo.material</uri>
            </script>
          </material>
        </visual>
        <self_collide>0</self_collide>
        <enable_wind>0</enable_wind>
        <kinematic>0</kinematic>
      </link>
      <plugin name='gazebo_ros_control' filename='libgazebo_ros_control.so'>
        <robotNamespace>/</robotNamespace>
      </plugin>
      <plugin name='camera' filename='librealsense_gazebo_plugin.so'>
        <depthUpdateRate>30</depthUpdateRate>
        <colorUpdateRate>30</colorUpdateRate>
        <infraredUpdateRate>30</infraredUpdateRate>
        <depthTopicName>depth/image_raw</depthTopicName>
        <depthCameraInfoTopicName>depth/camera_info</depthCameraInfoTopicName>
        <colorTopicName>color/image_raw</colorTopicName>
        <colorCameraInfoTopicName>color/camera_info</colorCameraInfoTopicName>
        <infrared1TopicName>infrared/image_raw</infrared1TopicName>
        <infrared1CameraInfoTopicName>infrared/camera_info</infrared1CameraInfoTopicName>
        <infrared2TopicName>infrared2/image_raw</infrared2TopicName>
        <infrared2CameraInfoTopicName>infrared2/camera_info</infrared2CameraInfoTopicName>
        <colorOpticalframeName>camera_color_optical_frame</colorOpticalframeName>
        <depthOpticalframeName>camera_depth_optical_frame</depthOpticalframeName>
        <infrared1OpticalframeName>camera_left_ir_optical_frame</infrared1OpticalframeName>
        <infrared2OpticalframeName>camera_right_ir_optical_frame</infrared2OpticalframeName>
        <rangeMinDepth>0.1</rangeMinDepth>
        <rangeMaxDepth>10</rangeMaxDepth>
        <pointCloud>1</pointCloud>
        <pointCloudTopicName>depth/color/points</pointCloudTopicName>
        <pointCloudCutoff>0.15</pointCloudCutoff>
        <pointCloudCutoffMax>10</pointCloudCutoffMax>
        <robotNamespace>/</robotNamespace>
      </plugin>
      <frame name='caster_joint' attached_to='base_link'>
        <pose>-0.245 0 0.032 -1.5708 0 0</pose>
      </frame>
      <frame name='caster_link' attached_to='caster_joint'/>
      <frame name='joint_aruco_left_base' attached_to='base_link'>
        <pose>-0.005 0.130497 0.159748 0 0 -1.5708</pose>
      </frame>
      <frame name='link_aruco_left_base' attached_to='joint_aruco_left_base'/>
      <frame name='joint_aruco_right_base' attached_to='base_link'>
        <pose>-0.001503 -0.130497 0.159748 0 0 -1.5708</pose>
      </frame>
      <frame name='link_aruco_right_base' attached_to='joint_aruco_right_base'/>
      <frame name='joint_laser' attached_to='base_link'>
        <pose>0.004 0 0.1664 0 -0 -3.14159</pose>
      </frame>
      <frame name='laser' attached_to='joint_laser'/>
      <frame name='joint_head' attached_to='link_mast'>
        <pose>0 1.33 0 1.5708 -1.57079 3.14159</pose>
      </frame>
      <frame name='link_head' attached_to='joint_head'/>
      <frame name='camera_accel_optical_joint' attached_to='camera_accel_frame'>
        <pose>0 0 0 -1.5708 -0 -1.5708</pose>
      </frame>
      <frame name='camera_accel_optical_frame' attached_to='camera_accel_optical_joint'/>
      <frame name='camera_accel_joint' attached_to='camera_link'>
        <pose>-0.01174 -0.00552 0.0051 0 -0 0</pose>
      </frame>
      <frame name='camera_accel_frame' attached_to='camera_accel_joint'/>
      <frame name='camera_color_optical_joint' attached_to='camera_color_frame'>
        <pose>0 0 0 -1.5708 -0 -1.5708</pose>
      </frame>
      <frame name='camera_color_optical_frame' attached_to='camera_color_optical_joint'/>
      <frame name='camera_color_joint' attached_to='camera_link'>
        <pose>0 0.015 0 0 -0 0</pose>
      </frame>
      <frame name='camera_color_frame' attached_to='camera_color_joint'/>
      <frame name='camera_depth_optical_joint' attached_to='camera_depth_frame'>
        <pose>0 0 0 -1.5708 -0 -1.5708</pose>
      </frame>
      <frame name='camera_depth_optical_frame' attached_to='camera_depth_optical_joint'/>
      <frame name='camera_depth_joint' attached_to='camera_link'>
        <pose>0 0 0 0 -0 0</pose>
      </frame>
      <frame name='camera_depth_frame' attached_to='camera_depth_joint'/>
      <frame name='camera_gyro_optical_joint' attached_to='camera_gyro_frame'>
        <pose>0 0 0 -1.5708 -0 -1.5708</pose>
      </frame>
      <frame name='camera_gyro_optical_frame' attached_to='camera_gyro_optical_joint'/>
      <frame name='camera_gyro_joint' attached_to='camera_link'>
        <pose>-0.01174 -0.00552 0.0051 0 -0 0</pose>
      </frame>
      <frame name='camera_gyro_frame' attached_to='camera_gyro_joint'/>
      <frame name='camera_infra1_optical_joint' attached_to='camera_infra1_frame'>
        <pose>0 0 0 -1.5708 -0 -1.5708</pose>
      </frame>
      <frame name='camera_infra1_optical_frame' attached_to='camera_infra1_optical_joint'/>
      <frame name='camera_infra1_joint' attached_to='camera_link'>
        <pose>0 0 0 0 -0 0</pose>
      </frame>
      <frame name='camera_infra1_frame' attached_to='camera_infra1_joint'/>
      <frame name='camera_infra2_optical_joint' attached_to='camera_infra2_frame'>
        <pose>0 0 0 -1.5708 -0 -1.5708</pose>
      </frame>
      <frame name='camera_infra2_optical_frame' attached_to='camera_infra2_optical_joint'/>
      <frame name='camera_infra2_joint' attached_to='camera_link'>
        <pose>0 -0.05 0 0 -0 0</pose>
      </frame>
      <frame name='camera_infra2_frame' attached_to='camera_infra2_joint'/>
      <frame name='camera_link_joint' attached_to='camera_bottom_screw_frame'>
        <pose>0.0106 0.0175 0.0125 0 -0 0</pose>
      </frame>
      <frame name='camera_link' attached_to='camera_link_joint'/>
      <frame name='camera_joint' attached_to='link_head_tilt'>
        <pose>0.03 -0.0122 0.0182 0 -0 0</pose>
      </frame>
      <frame name='camera_bottom_screw_frame' attached_to='camera_joint'/>
      <frame name='joint_respeaker' attached_to='link_mast'>
        <pose>0 1.37236 0.003031 -1.5708 -0.698132 -0</pose>
      </frame>
      <frame name='respeaker_base' attached_to='joint_respeaker'/>
      <frame name='joint_mast' attached_to='base_link'>
        <pose>-0.067 0.135 0.0284 1.5708 -0 0</pose>
      </frame>
      <frame name='link_mast' attached_to='joint_mast'/>
      <frame name='joint_arm_l4' attached_to='link_lift'>
        <pose>-0.2547 0 0 1.5708 0 -1.5708</pose>
      </frame>
      <frame name='link_arm_l4' attached_to='joint_arm_l4'/>
      <frame name='joint_aruco_inner_wrist' attached_to='link_arm_l0'>
        <pose>0.04725 -0.0119 -0.02725 3.14159 -0 3.14159</pose>
      </frame>
      <frame name='link_aruco_inner_wrist' attached_to='joint_aruco_inner_wrist'/>
      <frame name='joint_aruco_top_wrist' attached_to='link_arm_l0'>
        <pose>0.04725 0.029285 0 1.5708 -0 3.14159</pose>
      </frame>
      <frame name='link_aruco_top_wrist' attached_to='joint_aruco_top_wrist'/>
      <frame name='joint_grasp_center' attached_to='link_gripper'>
        <pose>-0.205478 0 -0.138154 0 -0 3.14158</pose>
      </frame>
      <frame name='link_grasp_center' attached_to='joint_grasp_center'/>
      <frame name='joint_gripper' attached_to='link_wrist_yaw'>
        <pose>0 0 0 3.14159 -0 -1.5708</pose>
      </frame>
      <frame name='link_gripper' attached_to='joint_gripper'/>
      <frame name='joint_gripper_fingertip_left' attached_to='link_gripper_finger_left'>
        <pose>0.171099 0.014912 0 -1.5708 -0 -2.5545</pose>
      </frame>
      <frame name='link_gripper_fingertip_left' attached_to='joint_gripper_fingertip_left'/>
      <frame name='joint_gripper_fingertip_right' attached_to='link_gripper_finger_right'>
        <pose>-0.171099 -0.014912 0 -1.5708 -0 0.58705</pose>
      </frame>
      <frame name='link_gripper_fingertip_right' attached_to='joint_gripper_fingertip_right'/>
      <frame name='joint_aruco_shoulder' attached_to='link_lift'>
        <pose>-0.013377 0.055854 0.086137 0 -0 0</pose>
      </frame>
      <frame name='link_aruco_shoulder' attached_to='joint_aruco_shoulder'/>
      <pose>0 0 0 0 -0 0</pose>
    </model>
    <model name='person_walking'>
      <link name='link'>
        <inertial>
          <pose>0 0 0.95 0 -0 0</pose>
          <mass>80</mass>
          <inertia>
            <ixx>27.82</ixx>
            <ixy>0</ixy>
            <ixz>0</ixz>
            <iyy>24.88</iyy>
            <iyz>0</iyz>
            <izz>4.57</izz>
          </inertia>
        </inertial>
        <collision name='bottom'>
          <pose>0 0 0.01 0 -0 0</pose>
          <geometry>
            <box>
              <size>0.35 0.75 0.02</size>
            </box>
          </geometry>
          <max_contacts>10</max_contacts>
          <surface>
            <contact>
              <ode/>
            </contact>
            <bounce/>
            <friction>
              <torsional>
                <ode/>
              </torsional>
              <ode/>
            </friction>
          </surface>
        </collision>
        <collision name='person'>
          <pose>0 0 -0.02 0 -0 0</pose>
          <geometry>
            <mesh>
              <uri>https://fuel.ignitionrobotics.org/1.0/gazebomstrling/models/walking person/1/files/meshes/walking.dae</uri>
            </mesh>
          </geometry>
          <max_contacts>10</max_contacts>
          <surface>
            <contact>
              <ode/>
            </contact>
            <bounce/>
            <friction>
              <torsional>
                <ode/>
              </torsional>
              <ode/>
            </friction>
          </surface>
        </collision>
        <visual name='visual'>
          <pose>0 0 -0.02 0 -0 0</pose>
          <geometry>
            <mesh>
              <uri>https://fuel.ignitionrobotics.org/1.0/gazebomstrling/models/walking person/1/files/meshes/walking.dae</uri>
            </mesh>
          </geometry>
        </visual>
        <self_collide>0</self_collide>
        <enable_wind>0</enable_wind>
        <kinematic>0</kinematic>
      </link>
      <pose>0.420835 -4.00989 1.5 0 -0 0</pose>
    </model>
    <state world_name='default'>
      <sim_time>360 213000000</sim_time>
      <real_time>671 322273094</real_time>
      <wall_time>1747272916 248055701</wall_time>
      <iterations>176805</iterations>
      <model name='ground_plane'>
        <pose>0 0 0 0 -0 0</pose>
        <scale>1 1 1</scale>
        <link name='link'>
          <pose>0 0 0 0 -0 0</pose>
          <velocity>0 0 0 0 -0 0</velocity>
          <acceleration>0 0 0 0 -0 0</acceleration>
          <wrench>0 0 0 0 -0 0</wrench>
        </link>
      </model>
      <model name='person_walking'>
        <pose>-0.360636 0.827176 0.447116 -1.80416 0.333717 3.13357</pose>
        <scale>1 1 1</scale>
        <link name='link'>
          <pose>-0.360636 0.827176 0.447116 -1.80416 0.333717 3.13357</pose>
          <velocity>0 0 0 0 -0 0</velocity>
          <acceleration>0.058231 -0.012662 -0.001086 -0.016531 1.24958 0.224149</acceleration>
          <wrench>4.6585 -1.01294 -0.086883 0 -0 0</wrench>
        </link>
      </model>
      <model name='robot'>
        <pose>0.221635 0.007784 -0.000422 -0.000821 0.001724 -1.40196</pose>
        <scale>1 1 1</scale>
        <link name='base_link'>
          <pose>0.221635 0.007784 -0.000422 -0.000821 0.001724 -1.40196</pose>
          <velocity>0.000106 0.000924 -0.00046 0.002019 -0.000383 -0.001684</velocity>
          <acceleration>0.210891 0.144098 0.237167 1.54889 1.50982 -1.11759</acceleration>
          <wrench>0.686108 0.468807 0.771593 0 -0 0</wrench>
        </link>
        <link name='link_arm_l0'>
          <pose>0.061971 0.085222 0.694865 1.57008 0.00177 -1.40185</pose>
          <velocity>0.002569 -0.000722 -0.000707 0.001173 -0.005886 0.01024</velocity>
          <acceleration>-0.290222 -0.57847 -0.379157 0.193785 -0.160861 -1.47402</acceleration>
          <wrench>-0.02467 -0.049172 -0.03223 0 -0 0</wrench>
        </link>
        <link name='link_arm_l1'>
          <pose>0.048417 0.08291 0.694875 1.57006 0.001766 -1.40186</pose>
          <velocity>0.002595 -0.000822 -0.000745 0.001057 -0.004582 0.008686</velocity>
          <acceleration>-0.344231 -0.499605 -0.330872 0.761437 0.085337 -1.45956</acceleration>
          <wrench>-0.017687 -0.025671 -0.017001 0 -0 0</wrench>
        </link>
        <link name='link_arm_l2'>
          <pose>0.061231 0.085097 0.694868 1.57004 0.00176 -1.40188</pose>
          <velocity>0.001876 -0.000629 -0.000585 0.000942 -0.003177 0.006346</velocity>
          <acceleration>-0.340621 -0.456534 -0.277768 1.38442 0.314465 -1.35208</acceleration>
          <wrench>-0.019463 -0.026086 -0.015871 0 -0 0</wrench>
        </link>
        <link name='link_arm_l3'>
          <pose>0.074045 0.087285 0.69486 1.57002 0.001754 -1.4019</pose>
          <velocity>0.00115 -0.000465 -0.000444 0.000805 -0.001714 0.003823</velocity>
          <acceleration>-0.334708 -0.412978 -0.214437 2.0798 0.528748 -1.26135</acceleration>
          <wrench>-0.021051 -0.025973 -0.013487 0 -0 0</wrench>
        </link>
        <link name='link_gripper_finger_left'>
          <pose>0.030995 -0.014419 0.617196 0.267948 0.454589 -2.41078</pose>
          <velocity>0.003801 -0.000936 -0.000952 0.001218 -0.005663 0.010097</velocity>
          <acceleration>0.318029 -1.09907 -0.416476 0.323855 -0.101432 -1.51376</acceleration>
          <wrench>0.01636 -0.056539 -0.021425 0 -0 0</wrench>
        </link>
        <link name='link_gripper_finger_right'>
          <pose>0.027598 0.005494 0.617232 -2.87032 -0.4527 -0.394362</pose>
          <velocity>0.00352 -0.000941 -0.000934 0.001406 -0.005311 0.009226</velocity>
          <acceleration>0.108622 -1.11453 -0.883081 0.554179 -0.077688 -1.57256</acceleration>
          <wrench>0.005588 -0.057334 -0.045428 0 -0 0</wrench>
        </link>
        <link name='link_head_pan'>
          <pose>0.224146 -0.00035 1.35476 -0.001768 -0.000694 -2.90196</pose>
          <velocity>-0.000312 -0.001723 -0.000505 0.002 -0.000309 -0.001248</velocity>
          <acceleration>-2.18409 -0.490546 -0.037263 -1.81616 0.169827 -1.63757</acceleration>
          <wrench>-0.059792 -0.013429 -0.00102 0 -0 0</wrench>
        </link>
        <link name='link_head_tilt'>
          <pose>0.231939 -0.026926 1.3014 1.56849 0.699304 -2.90344</pose>
          <velocity>-0.000327 -0.001652 -0.000566 0.001939 -0.000469 -0.000955</velocity>
          <acceleration>-1.96657 -0.527008 -0.103802 0.115837 -1.34051 -3.11673</acceleration>
          <wrench>-0.31901 -0.08549 -0.016838 0 -0 0</wrench>
        </link>
        <link name='link_left_wheel'>
          <pose>0.389608 0.036337 0.050603 -1.57157 0.052702 -1.40199</pose>
          <velocity>-0.000178 -9.8e-05 0.025314 0.001342 -0.004414 -0.001743</velocity>
          <acceleration>-0.128251 -0.075028 1.46864 -2.39962 -0.130479 -1.19309</acceleration>
          <wrench>-0.000548 -0.000321 0.006274 0 -0 0</wrench>
        </link>
        <link name='link_lift'>
          <pose>0.337936 0.132277 0.694645 0.001745 0.000806 0.168873</pose>
          <velocity>0.000386 -0.000257 -0.000374 0.000558 0.000137 0.000859</velocity>
          <acceleration>-0.441395 -0.196541 0.203661 -0.058027 1.07985 2.95532</acceleration>
          <wrench>-0.150196 -0.066878 0.069301 0 -0 0</wrench>
        </link>
        <link name='link_right_wheel'>
          <pose>0.053763 -0.020917 0.050622 -1.57164 0.030382 -1.40198</pose>
          <velocity>-0.000182 0.000216 -0.0268 0.002794 -0.004286 -0.001499</velocity>
          <acceleration>-0.364942 0.267331 -35.5059 -0.635107 -1.41149 -0.862981</acceleration>
          <wrench>-0.001559 0.001142 -0.151685 0 -0 0</wrench>
        </link>
        <link name='link_wrist_yaw'>
          <pose>0.075894 0.003454 0.66397 3.14088 0.00177 -1.40185</pose>
          <velocity>0.003357 -0.000504 -0.000664 0.001145 -0.005804 0.010531</velocity>
          <acceleration>-0.04616 -0.760613 -0.416798 0.251148 -0.110543 -1.48174</acceleration>
          <wrench>-0.006572 -0.108294 -0.059342 0 -0 0</wrench>
        </link>
      </model>
      <light name='sun'>
        <pose>0 0 10 0 -0 0</pose>
      </light>
    </state>
    <gui fullscreen='0'>
      <camera name='user_camera'>
        <pose>-3.35038 0.009049 1.64621 0 0.135644 0.188204</pose>
        <view_controller>orbit</view_controller>
        <projection_type>perspective</projection_type>
      </camera>
    </gui>
  </world>
</sdf>
