<sdf version='1.7'>
  <world name='default'>
    <light name='sun' type='directional'>
      <cast_shadows>1</cast_shadows>
      <pose>0 0 10 0 -0 0</pose>
      <diffuse>0.8 0.8 0.8 1</diffuse>
      <specular>0.2 0.2 0.2 1</specular>
      <attenuation>
        <range>1000</range>
        <constant>0.9</constant>
        <linear>0.01</linear>
        <quadratic>0.001</quadratic>
      </attenuation>
      <direction>-0.5 0.1 -0.9</direction>
      <spot>
        <inner_angle>0</inner_angle>
        <outer_angle>0</outer_angle>
        <falloff>0</falloff>
      </spot>
    </light>
    <model name='ground_plane'>
      <static>1</static>
      <link name='link'>
        <collision name='collision'>
          <geometry>
            <plane>
              <normal>0 0 1</normal>
              <size>100 100</size>
            </plane>
          </geometry>
          <surface>
            <contact>
              <collide_bitmask>65535</collide_bitmask>
              <ode/>
            </contact>
            <friction>
              <ode>
                <mu>100</mu>
                <mu2>50</mu2>
              </ode>
              <torsional>
                <ode/>
              </torsional>
            </friction>
            <bounce/>
          </surface>
          <max_contacts>10</max_contacts>
        </collision>
        <visual name='visual'>
          <cast_shadows>0</cast_shadows>
          <geometry>
            <plane>
              <normal>0 0 1</normal>
              <size>100 100</size>
            </plane>
          </geometry>
          <material>
            <script>
              <uri>file://media/materials/scripts/gazebo.material</uri>
              <name>Gazebo/Grey</name>
            </script>
          </material>
        </visual>
        <self_collide>0</self_collide>
        <enable_wind>0</enable_wind>
        <kinematic>0</kinematic>
      </link>
    </model>
    <gravity>0 0 -9.8</gravity>
    <magnetic_field>6e-06 2.3e-05 -4.2e-05</magnetic_field>
    <atmosphere type='adiabatic'/>
    <physics type='ode'>
      <max_step_size>0.001</max_step_size>
      <real_time_factor>1</real_time_factor>
      <real_time_update_rate>1000</real_time_update_rate>
    </physics>
    <scene>
      <ambient>0.4 0.4 0.4 1</ambient>
      <background>0.7 0.7 0.7 1</background>
      <shadows>1</shadows>
    </scene>
    <wind/>
    <spherical_coordinates>
      <surface_model>EARTH_WGS84</surface_model>
      <latitude_deg>0</latitude_deg>
      <longitude_deg>0</longitude_deg>
      <elevation>0</elevation>
      <heading_deg>0</heading_deg>
    </spherical_coordinates>
    <model name='robot'>
      <link name='base_link'>
        <inertial>
          <pose>-0.082202 0.081078 0.514938 0 -0 0</pose>
          <mass>3.25338</mass>
          <inertia>
            <ixx>0.51377</ixx>
            <ixy>-0.00420458</ixy>
            <ixz>-0.0319455</ixz>
            <iyy>0.505296</iyy>
            <iyz>-0.0634148</iyz>
            <izz>0.0236301</izz>
          </inertia>
        </inertial>
        <collision name='base_link_collision'>
          <pose>0 0 0 0 -0 0</pose>
          <geometry>
            <mesh>
              <scale>1 1 1</scale>
              <uri>/home/sandisk/koyo_ws/stretch_ws/src/stretch_ros/stretch_description/meshes/base_link.STL</uri>
            </mesh>
          </geometry>
          <surface>
            <contact>
              <ode/>
            </contact>
            <friction>
              <ode/>
              <torsional>
                <ode/>
              </torsional>
            </friction>
            <bounce/>
          </surface>
          <max_contacts>10</max_contacts>
        </collision>
        <collision name='base_link_fixed_joint_lump__caster_link_collision_1'>
          <pose>-0.245 0 0.032 -1.5708 0 0</pose>
          <geometry>
            <sphere>
              <radius>0.032</radius>
            </sphere>
          </geometry>
          <surface>
            <contact>
              <ode>
                <min_depth>0.001</min_depth>
              </ode>
            </contact>
            <friction>
              <ode>
                <mu>0</mu>
                <mu2>0</mu2>
              </ode>
              <torsional>
                <ode/>
              </torsional>
            </friction>
            <bounce/>
          </surface>
          <max_contacts>10</max_contacts>
        </collision>
        <collision name='base_link_fixed_joint_lump__link_aruco_left_base_collision_2'>
          <pose>-0.005 0.130497 0.159748 0 0 -1.5708</pose>
          <geometry>
            <mesh>
              <scale>1 1 1</scale>
              <uri>/home/sandisk/koyo_ws/stretch_ws/src/stretch_ros/stretch_description/meshes/link_aruco_left_base.STL</uri>
            </mesh>
          </geometry>
          <surface>
            <contact>
              <ode/>
            </contact>
            <friction>
              <ode/>
              <torsional>
                <ode/>
              </torsional>
            </friction>
            <bounce/>
          </surface>
          <max_contacts>10</max_contacts>
        </collision>
        <collision name='base_link_fixed_joint_lump__link_aruco_right_base_collision_3'>
          <pose>-0.001503 -0.130497 0.159748 0 0 -1.5708</pose>
          <geometry>
            <mesh>
              <scale>1 1 1</scale>
              <uri>/home/sandisk/koyo_ws/stretch_ws/src/stretch_ros/stretch_description/meshes/link_aruco_right_base.STL</uri>
            </mesh>
          </geometry>
          <surface>
            <contact>
              <ode/>
            </contact>
            <friction>
              <ode/>
              <torsional>
                <ode/>
              </torsional>
            </friction>
            <bounce/>
          </surface>
          <max_contacts>10</max_contacts>
        </collision>
        <collision name='base_link_fixed_joint_lump__laser_collision_4'>
          <pose>0.004 0 0.1664 0 0 -3.14159</pose>
          <geometry>
            <mesh>
              <scale>1 1 1</scale>
              <uri>/home/sandisk/koyo_ws/stretch_ws/src/stretch_ros/stretch_description/meshes/laser.STL</uri>
            </mesh>
          </geometry>
          <surface>
            <contact>
              <ode/>
            </contact>
            <friction>
              <ode/>
              <torsional>
                <ode/>
              </torsional>
            </friction>
            <bounce/>
          </surface>
          <max_contacts>10</max_contacts>
        </collision>
        <collision name='base_link_fixed_joint_lump__link_mast_collision_5'>
          <pose>-0.067 0.135 0.0284 1.5708 -0 0</pose>
          <geometry>
            <mesh>
              <scale>1 1 1</scale>
              <uri>/home/sandisk/koyo_ws/stretch_ws/src/stretch_ros/stretch_description/meshes/link_mast.STL</uri>
            </mesh>
          </geometry>
          <surface>
            <contact>
              <ode/>
            </contact>
            <friction>
              <ode/>
              <torsional>
                <ode/>
              </torsional>
            </friction>
            <bounce/>
          </surface>
          <max_contacts>10</max_contacts>
        </collision>
        <collision name='base_link_fixed_joint_lump__link_head_collision_6'>
          <pose>-0.067 0.134995 1.3584 7e-06 4e-06 -1.5708</pose>
          <geometry>
            <mesh>
              <scale>1 1 1</scale>
              <uri>/home/sandisk/koyo_ws/stretch_ws/src/stretch_ros/stretch_description/meshes/link_head.STL</uri>
            </mesh>
          </geometry>
          <surface>
            <contact>
              <ode/>
            </contact>
            <friction>
              <ode>
                <mu>100</mu>
                <mu2>200</mu2>
              </ode>
              <torsional>
                <ode/>
              </torsional>
            </friction>
            <bounce/>
          </surface>
          <max_contacts>10</max_contacts>
        </collision>
        <collision name='base_link_fixed_joint_lump__respeaker_base_collision_7'>
          <pose>-0.067 0.131964 1.40076 3e-06 2e-06 -0.698132</pose>
          <geometry>
            <mesh>
              <scale>1 1 1</scale>
              <uri>/home/sandisk/koyo_ws/stretch_ws/src/stretch_ros/stretch_description/meshes/respeaker_base.STL</uri>
            </mesh>
          </geometry>
          <surface>
            <contact>
              <ode/>
            </contact>
            <friction>
              <ode/>
              <torsional>
                <ode/>
              </torsional>
            </friction>
            <bounce/>
          </surface>
          <max_contacts>10</max_contacts>
        </collision>
        <visual name='base_link_visual'>
          <pose>0 0 0 0 -0 0</pose>
          <geometry>
            <mesh>
              <scale>1 1 1</scale>
              <uri>/home/sandisk/koyo_ws/stretch_ws/src/stretch_ros/stretch_description/meshes/base_link.STL</uri>
            </mesh>
          </geometry>
          <material>
            <script>
              <name>Gazebo/Gray</name>
              <uri>file://media/materials/scripts/gazebo.material</uri>
            </script>
          </material>
        </visual>
        <visual name='base_link_fixed_joint_lump__caster_link_visual_1'>
          <pose>-0.245 0 0.032 -1.5708 0 0</pose>
          <geometry>
            <mesh>
              <scale>1 1 1</scale>
              <uri>/home/sandisk/koyo_ws/stretch_ws/src/stretch_ros/stretch_description/meshes/omni_wheel_m.STL</uri>
            </mesh>
          </geometry>
          <material>
            <script>
              <name>Gazebo/Blue</name>
              <uri>file://media/materials/scripts/gazebo.material</uri>
            </script>
          </material>
        </visual>
        <visual name='base_link_fixed_joint_lump__link_aruco_left_base_visual_2'>
          <pose>-0.005 0.130497 0.159748 0 0 -1.5708</pose>
          <geometry>
            <mesh>
              <scale>1 1 1</scale>
              <uri>/home/sandisk/koyo_ws/stretch_ws/src/stretch_ros/stretch_description/meshes/link_aruco_left_base.STL</uri>
            </mesh>
          </geometry>
          <material>
            <script>
              <name>Gazebo/Black</name>
              <uri>file://media/materials/scripts/gazebo.material</uri>
            </script>
          </material>
        </visual>
        <visual name='base_link_fixed_joint_lump__link_aruco_right_base_visual_3'>
          <pose>-0.001503 -0.130497 0.159748 0 0 -1.5708</pose>
          <geometry>
            <mesh>
              <scale>1 1 1</scale>
              <uri>/home/sandisk/koyo_ws/stretch_ws/src/stretch_ros/stretch_description/meshes/link_aruco_right_base.STL</uri>
            </mesh>
          </geometry>
          <material>
            <script>
              <name>Gazebo/Black</name>
              <uri>file://media/materials/scripts/gazebo.material</uri>
            </script>
          </material>
        </visual>
        <visual name='base_link_fixed_joint_lump__laser_visual_4'>
          <pose>0.004 0 0.1664 0 0 -3.14159</pose>
          <geometry>
            <mesh>
              <scale>1 1 1</scale>
              <uri>/home/sandisk/koyo_ws/stretch_ws/src/stretch_ros/stretch_description/meshes/laser.STL</uri>
            </mesh>
          </geometry>
          <material>
            <script>
              <name>Gazebo/Black</name>
              <uri>file://media/materials/scripts/gazebo.material</uri>
            </script>
          </material>
        </visual>
        <visual name='base_link_fixed_joint_lump__link_mast_visual_5'>
          <pose>-0.067 0.135 0.0284 1.5708 -0 0</pose>
          <geometry>
            <mesh>
              <scale>1 1 1</scale>
              <uri>/home/sandisk/koyo_ws/stretch_ws/src/stretch_ros/stretch_description/meshes/link_mast.STL</uri>
            </mesh>
          </geometry>
          <material>
            <script>
              <name>Gazebo/Gray</name>
              <uri>file://media/materials/scripts/gazebo.material</uri>
            </script>
          </material>
        </visual>
        <visual name='base_link_fixed_joint_lump__link_head_visual_6'>
          <pose>-0.067 0.134995 1.3584 7e-06 4e-06 -1.5708</pose>
          <geometry>
            <mesh>
              <scale>1 1 1</scale>
              <uri>/home/sandisk/koyo_ws/stretch_ws/src/stretch_ros/stretch_description/meshes/link_head.STL</uri>
            </mesh>
          </geometry>
          <material>
            <script>
              <name>Gazebo/Gray</name>
              <uri>file://media/materials/scripts/gazebo.material</uri>
            </script>
          </material>
        </visual>
        <visual name='base_link_fixed_joint_lump__respeaker_base_visual_7'>
          <pose>-0.067 0.131964 1.40076 3e-06 2e-06 -0.698132</pose>
          <geometry>
            <mesh>
              <scale>1 1 1</scale>
              <uri>/home/sandisk/koyo_ws/stretch_ws/src/stretch_ros/stretch_description/meshes/respeaker_base.STL</uri>
            </mesh>
          </geometry>
          <material>
            <script>
              <name>Gazebo/Green</name>
              <uri>file://media/materials/scripts/gazebo.material</uri>
            </script>
          </material>
        </visual>
        <sensor name='base_imu' type='imu'>
          <always_on>1</always_on>
          <visualize>0</visualize>
          <plugin name='imu_plugin' filename='libgazebo_ros_imu_sensor.so'>
            <topicName>imu/data</topicName>
            <bodyName>base_link</bodyName>
            <updateRateHZ>25.0</updateRateHZ>
            <gaussianNoise>0.001</gaussianNoise>
            <xyzOffset>0 0 0</xyzOffset>
            <rpyOffset>0 0 0</rpyOffset>
            <frameName>base_link</frameName>
            <initialOrientationAsReference>0</initialOrientationAsReference>
            <robotNamespace>/</robotNamespace>
          </plugin>
          <pose>0 0 0 0 -0 0</pose>
          <imu/>
        </sensor>
        <gravity>1</gravity>
        <sensor name='laser_sensor' type='ray'>
          <visualize>0</visualize>
          <update_rate>5.5</update_rate>
          <ray>
            <scan>
              <horizontal>
                <samples>2000</samples>
                <resolution>1</resolution>
                <min_angle>-0.9</min_angle>
                <max_angle>5</max_angle>
              </horizontal>
              <vertical>
                <samples>1</samples>
                <min_angle>0</min_angle>
                <max_angle>0</max_angle>
              </vertical>
            </scan>
            <range>
              <min>0.15</min>
              <max>12</max>
              <resolution>0.01</resolution>
            </range>
            <noise>
              <type>gaussian</type>
              <mean>0</mean>
              <stddev>0.001</stddev>
            </noise>
          </ray>
          <plugin name='gazebo_ros_lidar_controller' filename='libgazebo_ros_laser.so'>
            <topicName>scan</topicName>
            <frameName>laser</frameName>
            <robotNamespace>/</robotNamespace>
          </plugin>
          <pose>0.004 0 0.1664 0 -0 -3.14159</pose>
        </sensor>
        <self_collide>0</self_collide>
        <enable_wind>0</enable_wind>
        <kinematic>0</kinematic>
      </link>
      <joint name='joint_left_wheel' type='revolute'>
        <pose relative_to='base_link'>0 0.17035 0.0508 -1.5708 0 0</pose>
        <parent>base_link</parent>
        <child>link_left_wheel</child>
        <axis>
          <xyz>0 0 1</xyz>
          <limit>
            <lower>-1e+16</lower>
            <upper>1e+16</upper>
          </limit>
          <dynamics>
            <damping>21.75</damping>
            <friction>10.48</friction>
            <spring_reference>0</spring_reference>
            <spring_stiffness>0</spring_stiffness>
          </dynamics>
        </axis>
      </joint>
      <link name='link_left_wheel'>
        <pose relative_to='joint_left_wheel'>0 0 0 0 -0 0</pose>
        <inertial>
          <pose>-0 -0 -0.037544 0 -0 0</pose>
          <mass>0.0042721</mass>
          <inertia>
            <ixx>0.001</ixx>
            <ixy>0</ixy>
            <ixz>0</ixz>
            <iyy>0.001</iyy>
            <iyz>0</iyz>
            <izz>0.001</izz>
          </inertia>
        </inertial>
        <collision name='link_left_wheel_collision'>
          <pose>0 0 0 0 -0 0</pose>
          <geometry>
            <mesh>
              <scale>1 1 1</scale>
              <uri>/home/sandisk/koyo_ws/stretch_ws/src/stretch_ros/stretch_description/meshes/link_left_wheel.STL</uri>
            </mesh>
          </geometry>
          <surface>
            <contact>
              <ode>
                <kp>1e+07</kp>
                <kd>100</kd>
                <min_depth>0.001</min_depth>
              </ode>
            </contact>
            <friction>
              <ode>
                <mu>100</mu>
                <mu2>200</mu2>
              </ode>
              <torsional>
                <ode/>
              </torsional>
            </friction>
            <bounce/>
          </surface>
          <max_contacts>10</max_contacts>
        </collision>
        <visual name='link_left_wheel_visual'>
          <pose>0 0 0 0 -0 0</pose>
          <geometry>
            <mesh>
              <scale>1 1 1</scale>
              <uri>/home/sandisk/koyo_ws/stretch_ws/src/stretch_ros/stretch_description/meshes/link_left_wheel.STL</uri>
            </mesh>
          </geometry>
          <material>
            <script>
              <name>Gazebo/Blue</name>
              <uri>file://media/materials/scripts/gazebo.material</uri>
            </script>
          </material>
        </visual>
        <self_collide>0</self_collide>
        <enable_wind>0</enable_wind>
        <kinematic>0</kinematic>
      </link>
      <joint name='joint_head_pan' type='revolute'>
        <pose relative_to='base_link'>0.0061 -5e-06 1.3552 4e-06 -7e-06 -0</pose>
        <parent>base_link</parent>
        <child>link_head_pan</child>
        <axis>
          <xyz>0 0 1</xyz>
          <limit>
            <lower>-3.9</lower>
            <upper>1.5</upper>
            <effort>100</effort>
            <velocity>1</velocity>
          </limit>
          <dynamics>
            <spring_reference>0</spring_reference>
            <spring_stiffness>0</spring_stiffness>
          </dynamics>
        </axis>
      </joint>
      <link name='link_head_pan'>
        <pose relative_to='joint_head_pan'>0 0 0 0 -0 0</pose>
        <inertial>
          <pose>-0.000327 0.0085 0.00013 0 -0 0</pose>
          <mass>0.0273764</mass>
          <inertia>
            <ixx>0.001</ixx>
            <ixy>0</ixy>
            <ixz>0</ixz>
            <iyy>0.001</iyy>
            <iyz>0</iyz>
            <izz>0.001</izz>
          </inertia>
        </inertial>
        <collision name='link_head_pan_collision'>
          <pose>0 0 0 0 -0 0</pose>
          <geometry>
            <mesh>
              <scale>1 1 1</scale>
              <uri>/home/sandisk/koyo_ws/stretch_ws/src/stretch_ros/stretch_description/meshes/link_head_pan.STL</uri>
            </mesh>
          </geometry>
          <surface>
            <contact>
              <ode>
                <kp>1e+07</kp>
                <kd>100</kd>
                <min_depth>0.001</min_depth>
              </ode>
            </contact>
            <friction>
              <ode>
                <mu>100</mu>
                <mu2>200</mu2>
              </ode>
              <torsional>
                <ode/>
              </torsional>
            </friction>
            <bounce/>
          </surface>
          <max_contacts>10</max_contacts>
        </collision>
        <visual name='link_head_pan_visual'>
          <pose>0 0 0 0 -0 0</pose>
          <geometry>
            <mesh>
              <scale>1 1 1</scale>
              <uri>/home/sandisk/koyo_ws/stretch_ws/src/stretch_ros/stretch_description/meshes/link_head_pan.STL</uri>
            </mesh>
          </geometry>
          <material>
            <script>
              <name>Gazebo/Gray</name>
              <uri>file://media/materials/scripts/gazebo.material</uri>
            </script>
          </material>
        </visual>
        <self_collide>0</self_collide>
        <enable_wind>0</enable_wind>
        <kinematic>0</kinematic>
      </link>
      <joint name='joint_head_tilt' type='revolute'>
        <pose relative_to='link_head_pan'>-0.0013 0.027762 -0.053311 1.5708 -0 0</pose>
        <parent>link_head_pan</parent>
        <child>link_head_tilt</child>
        <axis>
          <xyz>0 0 1</xyz>
          <limit>
            <lower>-1.53</lower>
            <upper>0.79</upper>
            <effort>100</effort>
            <velocity>1</velocity>
          </limit>
          <dynamics>
            <spring_reference>0</spring_reference>
            <spring_stiffness>0</spring_stiffness>
          </dynamics>
        </axis>
      </joint>
      <link name='link_head_tilt'>
        <pose relative_to='joint_head_tilt'>0 0 0 0 -0 0</pose>
        <inertial>
          <pose>0.021939 -0.009452 0.030425 0 -0 0</pose>
          <mass>0.162217</mass>
          <inertia>
            <ixx>0.00490943</ixx>
            <ixy>-3.56401e-05</ixy>
            <ixz>-6.63879e-07</ixz>
            <iyy>0.00154403</iyy>
            <iyz>-5.24815e-07</iyz>
            <izz>0.00495252</izz>
          </inertia>
        </inertial>
        <collision name='link_head_tilt_collision'>
          <pose>0 0 0 0 -0 0</pose>
          <geometry>
            <mesh>
              <scale>1 1 1</scale>
              <uri>/home/sandisk/koyo_ws/stretch_ws/src/stretch_ros/stretch_description/meshes/link_head_tilt.STL</uri>
            </mesh>
          </geometry>
          <surface>
            <contact>
              <ode>
                <kp>1e+07</kp>
                <kd>100</kd>
                <min_depth>0.001</min_depth>
              </ode>
            </contact>
            <friction>
              <ode>
                <mu>100</mu>
                <mu2>200</mu2>
              </ode>
              <torsional>
                <ode/>
              </torsional>
            </friction>
            <bounce/>
          </surface>
          <max_contacts>10</max_contacts>
        </collision>
        <collision name='link_head_tilt_fixed_joint_lump__camera_link_collision_1'>
          <pose>0.0406 -0.0122 0.0307 0 -0 0</pose>
          <geometry>
            <box>
              <size>0.02505 0.09 0.025</size>
            </box>
          </geometry>
          <max_contacts>10</max_contacts>
          <surface>
            <contact>
              <ode/>
            </contact>
            <bounce/>
            <friction>
              <torsional>
                <ode/>
              </torsional>
              <ode/>
            </friction>
          </surface>
        </collision>
        <visual name='link_head_tilt_visual'>
          <pose>0 0 0 0 -0 0</pose>
          <geometry>
            <mesh>
              <scale>1 1 1</scale>
              <uri>/home/sandisk/koyo_ws/stretch_ws/src/stretch_ros/stretch_description/meshes/link_head_tilt.STL</uri>
            </mesh>
          </geometry>
          <material>
            <script>
              <name>Gazebo/Gray</name>
              <uri>file://media/materials/scripts/gazebo.material</uri>
            </script>
          </material>
        </visual>
        <visual name='link_head_tilt_fixed_joint_lump__camera_link_visual_1'>
          <pose>0.0449 -0.0122 0.0307 1.5708 -0 1.5708</pose>
          <geometry>
            <mesh>
              <scale>1 1 1</scale>
              <uri>/opt/ros/noetic/share/realsense2_description/meshes/d435.dae</uri>
            </mesh>
          </geometry>
        </visual>
        <sensor name='color' type='camera'>
          <camera name='__default__'>
            <horizontal_fov>1.50098</horizontal_fov>
            <image>
              <width>640</width>
              <height>480</height>
              <format>RGB_INT8</format>
            </image>
            <clip>
              <near>0.1</near>
              <far>100</far>
            </clip>
            <noise>
              <type>gaussian</type>
              <mean>0</mean>
              <stddev>0.007</stddev>
            </noise>
          </camera>
          <always_on>1</always_on>
          <update_rate>30</update_rate>
          <visualize>0</visualize>
          <pose>0.0406 0.0203 0.0307 0 -0 0</pose>
        </sensor>
        <sensor name='depth' type='depth'>
          <camera name='__default__'>
            <horizontal_fov>1.50098</horizontal_fov>
            <image>
              <width>640</width>
              <height>480</height>
            </image>
            <clip>
              <near>0.1</near>
              <far>100</far>
            </clip>
            <noise>
              <type>gaussian</type>
              <mean>0</mean>
              <stddev>0.007</stddev>
            </noise>
          </camera>
          <always_on>1</always_on>
          <update_rate>30</update_rate>
          <visualize>0</visualize>
          <pose>0.0406 0.0053 0.0307 0 -0 0</pose>
        </sensor>
        <gravity>1</gravity>
        <sensor name='imu_sensor' type='imu'>
          <always_on>1</always_on>
          <visualize>0</visualize>
          <plugin name='imu_plugin' filename='libgazebo_ros_imu_sensor.so'>
            <topicName>camera/imu/data</topicName>
            <bodyName>camera_gyro_frame</bodyName>
            <updateRateHZ>50.0</updateRateHZ>
            <gaussianNoise>0.001</gaussianNoise>
            <xyzOffset>0 0 0</xyzOffset>
            <rpyOffset>0 0 0</rpyOffset>
            <frameName>camera_gyro_frame</frameName>
            <initialOrientationAsReference>0</initialOrientationAsReference>
            <robotNamespace>/</robotNamespace>
          </plugin>
          <pose>0.02886 -0.00022 0.0358 0 -0 0</pose>
          <imu/>
        </sensor>
        <sensor name='ired1' type='camera'>
          <camera name='__default__'>
            <horizontal_fov>1.50098</horizontal_fov>
            <image>
              <width>640</width>
              <height>480</height>
              <format>L_INT8</format>
            </image>
            <clip>
              <near>0.1</near>
              <far>100</far>
            </clip>
            <noise>
              <type>gaussian</type>
              <mean>0</mean>
              <stddev>0.007</stddev>
            </noise>
          </camera>
          <always_on>1</always_on>
          <update_rate>30</update_rate>
          <visualize>0</visualize>
          <pose>0.0406 0.0053 0.0307 0 -0 0</pose>
        </sensor>
        <sensor name='ired2' type='camera'>
          <camera name='__default__'>
            <horizontal_fov>1.50098</horizontal_fov>
            <image>
              <width>640</width>
              <height>480</height>
              <format>L_INT8</format>
            </image>
            <clip>
              <near>0.1</near>
              <far>100</far>
            </clip>
            <noise>
              <type>gaussian</type>
              <mean>0</mean>
              <stddev>0.007</stddev>
            </noise>
          </camera>
          <always_on>1</always_on>
          <update_rate>30</update_rate>
          <visualize>0</visualize>
          <pose>0.0406 -0.0447 0.0307 0 -0 0</pose>
        </sensor>
        <self_collide>0</self_collide>
        <enable_wind>0</enable_wind>
        <kinematic>0</kinematic>
      </link>
      <joint name='joint_lift' type='prismatic'>
        <pose relative_to='base_link'>-0.104385 0.134999 0.195 -4e-06 -4e-06 1.5708</pose>
        <parent>base_link</parent>
        <child>link_lift</child>
        <axis>
          <xyz>0 0 1</xyz>
          <limit>
            <lower>0</lower>
            <upper>1.1</upper>
            <effort>100</effort>
            <velocity>1</velocity>
          </limit>
          <dynamics>
            <spring_reference>0</spring_reference>
            <spring_stiffness>0</spring_stiffness>
          </dynamics>
        </axis>
      </joint>
      <link name='link_lift'>
        <pose relative_to='joint_lift'>0 0 0 0 -0 0</pose>
        <inertial>
          <pose>-0.057389 0.030718 0.010683 0 -0 0</pose>
          <mass>0.340275</mass>
          <inertia>
            <ixx>0.000615788</ixx>
            <ixy>-0.000119232</ixy>
            <ixz>-0.000112834</ixz>
            <iyy>0.00133783</iyy>
            <iyz>-3.42328e-05</iyz>
            <izz>0.00147485</izz>
          </inertia>
        </inertial>
        <collision name='link_lift_collision'>
          <pose>0 0 0 0 -0 0</pose>
          <geometry>
            <mesh>
              <scale>1 1 1</scale>
              <uri>/home/sandisk/koyo_ws/stretch_ws/src/stretch_ros/stretch_description/meshes/link_lift.STL</uri>
            </mesh>
          </geometry>
          <surface>
            <contact>
              <ode>
                <kp>1e+07</kp>
                <kd>100</kd>
                <min_depth>0.001</min_depth>
              </ode>
            </contact>
            <friction>
              <ode>
                <mu>10000</mu>
                <mu2>10000</mu2>
              </ode>
              <torsional>
                <ode/>
              </torsional>
            </friction>
            <bounce/>
          </surface>
          <max_contacts>10</max_contacts>
        </collision>
        <collision name='link_lift_fixed_joint_lump__link_arm_l4_collision_1'>
          <pose>-0.2547 0 0 1.5708 0 -1.5708</pose>
          <geometry>
            <mesh>
              <scale>1 1 1</scale>
              <uri>/home/sandisk/koyo_ws/stretch_ws/src/stretch_ros/stretch_description/meshes/link_arm_l4.STL</uri>
            </mesh>
          </geometry>
          <surface>
            <contact>
              <ode>
                <kp>1e+07</kp>
                <kd>100</kd>
                <min_depth>0.001</min_depth>
              </ode>
            </contact>
            <friction>
              <ode>
                <mu>100</mu>
                <mu2>200</mu2>
              </ode>
              <torsional>
                <ode/>
              </torsional>
            </friction>
            <bounce/>
          </surface>
          <max_contacts>10</max_contacts>
        </collision>
        <collision name='link_lift_fixed_joint_lump__link_aruco_shoulder_collision_2'>
          <pose>-0.013377 0.055854 0.086137 0 -0 0</pose>
          <geometry>
            <mesh>
              <scale>1 1 1</scale>
              <uri>/home/sandisk/koyo_ws/stretch_ws/src/stretch_ros/stretch_description/meshes/link_aruco_shoulder.STL</uri>
            </mesh>
          </geometry>
          <surface>
            <contact>
              <ode/>
            </contact>
            <friction>
              <ode/>
              <torsional>
                <ode/>
              </torsional>
            </friction>
            <bounce/>
          </surface>
          <max_contacts>10</max_contacts>
        </collision>
        <visual name='link_lift_visual'>
          <pose>0 0 0 0 -0 0</pose>
          <geometry>
            <mesh>
              <scale>1 1 1</scale>
              <uri>/home/sandisk/koyo_ws/stretch_ws/src/stretch_ros/stretch_description/meshes/link_lift.STL</uri>
            </mesh>
          </geometry>
          <material>
            <script>
              <name>Gazebo/Black</name>
              <uri>file://media/materials/scripts/gazebo.material</uri>
            </script>
          </material>
        </visual>
        <visual name='link_lift_fixed_joint_lump__link_arm_l4_visual_1'>
          <pose>-0.2547 0 0 1.5708 0 -1.5708</pose>
          <geometry>
            <mesh>
              <scale>1 1 1</scale>
              <uri>/home/sandisk/koyo_ws/stretch_ws/src/stretch_ros/stretch_description/meshes/link_arm_l4.STL</uri>
            </mesh>
          </geometry>
          <material>
            <script>
              <name>Gazebo/Gray</name>
              <uri>file://media/materials/scripts/gazebo.material</uri>
            </script>
          </material>
        </visual>
        <visual name='link_lift_fixed_joint_lump__link_aruco_shoulder_visual_2'>
          <pose>-0.013377 0.055854 0.086137 0 -0 0</pose>
          <geometry>
            <mesh>
              <scale>1 1 1</scale>
              <uri>/home/sandisk/koyo_ws/stretch_ws/src/stretch_ros/stretch_description/meshes/link_aruco_shoulder.STL</uri>
            </mesh>
          </geometry>
          <material>
            <script>
              <name>Gazebo/Black</name>
              <uri>file://media/materials/scripts/gazebo.material</uri>
            </script>
          </material>
        </visual>
        <self_collide>0</self_collide>
        <enable_wind>0</enable_wind>
        <kinematic>0</kinematic>
      </link>
      <joint name='joint_arm_l3' type='prismatic'>
        <pose relative_to='link_lift'>-0.2677 0 -0 1.5708 0 -1.5708</pose>
        <parent>link_lift</parent>
        <child>link_arm_l3</child>
        <axis>
          <xyz>0 0 1</xyz>
          <limit>
            <lower>0</lower>
            <upper>0.13</upper>
            <effort>100</effort>
            <velocity>1</velocity>
          </limit>
          <dynamics>
            <spring_reference>0</spring_reference>
            <spring_stiffness>0</spring_stiffness>
          </dynamics>
        </axis>
      </joint>
      <link name='link_arm_l3'>
        <pose relative_to='joint_arm_l3'>0 0 0 0 -0 0</pose>
        <inertial>
          <pose>-1e-06 -2e-05 -0.09711 0 -0 0</pose>
          <mass>0.0628927</mass>
          <inertia>
            <ixx>0.001</ixx>
            <ixy>0</ixy>
            <ixz>0</ixz>
            <iyy>0.001</iyy>
            <iyz>0</iyz>
            <izz>0.001</izz>
          </inertia>
        </inertial>
        <collision name='link_arm_l3_collision'>
          <pose>0 0 0 0 -0 0</pose>
          <geometry>
            <mesh>
              <scale>1 1 1</scale>
              <uri>/home/sandisk/koyo_ws/stretch_ws/src/stretch_ros/stretch_description/meshes/link_arm_l3.STL</uri>
            </mesh>
          </geometry>
          <surface>
            <contact>
              <ode>
                <kp>1e+07</kp>
                <kd>100</kd>
                <min_depth>0.001</min_depth>
              </ode>
            </contact>
            <friction>
              <ode>
                <mu>100</mu>
                <mu2>200</mu2>
              </ode>
              <torsional>
                <ode/>
              </torsional>
            </friction>
            <bounce/>
          </surface>
          <max_contacts>10</max_contacts>
        </collision>
        <visual name='link_arm_l3_visual'>
          <pose>0 0 0 0 -0 0</pose>
          <geometry>
            <mesh>
              <scale>1 1 1</scale>
              <uri>/home/sandisk/koyo_ws/stretch_ws/src/stretch_ros/stretch_description/meshes/link_arm_l3.STL</uri>
            </mesh>
          </geometry>
          <material>
            <script>
              <name>Gazebo/Gray</name>
              <uri>file://media/materials/scripts/gazebo.material</uri>
            </script>
          </material>
        </visual>
        <self_collide>0</self_collide>
        <enable_wind>0</enable_wind>
        <kinematic>0</kinematic>
      </link>
      <joint name='joint_arm_l2' type='prismatic'>
        <pose relative_to='link_arm_l3'>0 0 0.013 0 -0 0</pose>
        <parent>link_arm_l3</parent>
        <child>link_arm_l2</child>
        <axis>
          <xyz>0 0 1</xyz>
          <limit>
            <lower>0</lower>
            <upper>0.13</upper>
            <effort>100</effort>
            <velocity>1</velocity>
          </limit>
          <dynamics>
            <spring_reference>0</spring_reference>
            <spring_stiffness>0</spring_stiffness>
          </dynamics>
        </axis>
      </joint>
      <link name='link_arm_l2'>
        <pose relative_to='joint_arm_l2'>0 0 0 0 -0 0</pose>
        <inertial>
          <pose>-1e-06 -2e-05 -0.096882 0 -0 0</pose>
          <mass>0.0571386</mass>
          <inertia>
            <ixx>0.001</ixx>
            <ixy>0</ixy>
            <ixz>0</ixz>
            <iyy>0.001</iyy>
            <iyz>0</iyz>
            <izz>0.001</izz>
          </inertia>
        </inertial>
        <collision name='link_arm_l2_collision'>
          <pose>0 0 0 0 -0 0</pose>
          <geometry>
            <mesh>
              <scale>1 1 1</scale>
              <uri>/home/sandisk/koyo_ws/stretch_ws/src/stretch_ros/stretch_description/meshes/link_arm_l2.STL</uri>
            </mesh>
          </geometry>
          <surface>
            <contact>
              <ode>
                <kp>1e+07</kp>
                <kd>100</kd>
                <min_depth>0.001</min_depth>
              </ode>
            </contact>
            <friction>
              <ode>
                <mu>100</mu>
                <mu2>200</mu2>
              </ode>
              <torsional>
                <ode/>
              </torsional>
            </friction>
            <bounce/>
          </surface>
          <max_contacts>10</max_contacts>
        </collision>
        <visual name='link_arm_l2_visual'>
          <pose>0 0 0 0 -0 0</pose>
          <geometry>
            <mesh>
              <scale>1 1 1</scale>
              <uri>/home/sandisk/koyo_ws/stretch_ws/src/stretch_ros/stretch_description/meshes/link_arm_l2.STL</uri>
            </mesh>
          </geometry>
          <material>
            <script>
              <name>Gazebo/Gray</name>
              <uri>file://media/materials/scripts/gazebo.material</uri>
            </script>
          </material>
        </visual>
        <self_collide>0</self_collide>
        <enable_wind>0</enable_wind>
        <kinematic>0</kinematic>
      </link>
      <joint name='joint_arm_l1' type='prismatic'>
        <pose relative_to='link_arm_l2'>0 0 0.013 0 -0 0</pose>
        <parent>link_arm_l2</parent>
        <child>link_arm_l1</child>
        <axis>
          <xyz>0 0 1</xyz>
          <limit>
            <lower>0</lower>
            <upper>0.13</upper>
            <effort>100</effort>
            <velocity>1</velocity>
          </limit>
          <dynamics>
            <spring_reference>0</spring_reference>
            <spring_stiffness>0</spring_stiffness>
          </dynamics>
        </axis>
      </joint>
      <link name='link_arm_l1'>
        <pose relative_to='joint_arm_l1'>0 0 0 0 -0 0</pose>
        <inertial>
          <pose>-1e-06 -2e-05 -0.096543 0 -0 0</pose>
          <mass>0.051382</mass>
          <inertia>
            <ixx>0.001</ixx>
            <ixy>0</ixy>
            <ixz>0</ixz>
            <iyy>0.001</iyy>
            <iyz>0</iyz>
            <izz>0.001</izz>
          </inertia>
        </inertial>
        <collision name='link_arm_l1_collision'>
          <pose>0 0 0 0 -0 0</pose>
          <geometry>
            <mesh>
              <scale>1 1 1</scale>
              <uri>/home/sandisk/koyo_ws/stretch_ws/src/stretch_ros/stretch_description/meshes/link_arm_l1.STL</uri>
            </mesh>
          </geometry>
          <surface>
            <contact>
              <ode>
                <kp>1e+07</kp>
                <kd>100</kd>
                <min_depth>0.001</min_depth>
              </ode>
            </contact>
            <friction>
              <ode>
                <mu>100</mu>
                <mu2>200</mu2>
              </ode>
              <torsional>
                <ode/>
              </torsional>
            </friction>
            <bounce/>
          </surface>
          <max_contacts>10</max_contacts>
        </collision>
        <visual name='link_arm_l1_visual'>
          <pose>0 0 0 0 -0 0</pose>
          <geometry>
            <mesh>
              <scale>1 1 1</scale>
              <uri>/home/sandisk/koyo_ws/stretch_ws/src/stretch_ros/stretch_description/meshes/link_arm_l1.STL</uri>
            </mesh>
          </geometry>
          <material>
            <script>
              <name>Gazebo/Gray</name>
              <uri>file://media/materials/scripts/gazebo.material</uri>
            </script>
          </material>
        </visual>
        <self_collide>0</self_collide>
        <enable_wind>0</enable_wind>
        <kinematic>0</kinematic>
      </link>
      <joint name='joint_arm_l0' type='prismatic'>
        <pose relative_to='link_arm_l1'>0 0 -0.01375 0 -0 0</pose>
        <parent>link_arm_l1</parent>
        <child>link_arm_l0</child>
        <axis>
          <xyz>0 0 1</xyz>
          <limit>
            <lower>0</lower>
            <upper>0.13</upper>
            <effort>100</effort>
            <velocity>1</velocity>
          </limit>
          <dynamics>
            <spring_reference>0</spring_reference>
            <spring_stiffness>0</spring_stiffness>
          </dynamics>
        </axis>
      </joint>
      <link name='link_arm_l0'>
        <pose relative_to='joint_arm_l0'>0 0 0 0 -0 0</pose>
        <inertial>
          <pose>0.027058 -0.001899 -0.037781 0 -0 0</pose>
          <mass>0.0850033</mass>
          <inertia>
            <ixx>0.001</ixx>
            <ixy>0</ixy>
            <ixz>0</ixz>
            <iyy>0.001</iyy>
            <iyz>0</iyz>
            <izz>0.001</izz>
          </inertia>
        </inertial>
        <collision name='link_arm_l0_collision'>
          <pose>0 0 0 0 -0 0</pose>
          <geometry>
            <mesh>
              <scale>1 1 1</scale>
              <uri>/home/sandisk/koyo_ws/stretch_ws/src/stretch_ros/stretch_description/meshes/link_arm_l0.STL</uri>
            </mesh>
          </geometry>
          <surface>
            <contact>
              <ode>
                <kp>1e+07</kp>
                <kd>100</kd>
                <min_depth>0.001</min_depth>
              </ode>
            </contact>
            <friction>
              <ode>
                <mu>100</mu>
                <mu2>200</mu2>
              </ode>
              <torsional>
                <ode/>
              </torsional>
            </friction>
            <bounce/>
          </surface>
          <max_contacts>10</max_contacts>
        </collision>
        <collision name='link_arm_l0_fixed_joint_lump__link_aruco_inner_wrist_collision_1'>
          <pose>0.04725 -0.0119 -0.02725 3.14159 -0 3.14159</pose>
          <geometry>
            <mesh>
              <scale>1 1 1</scale>
              <uri>/home/sandisk/koyo_ws/stretch_ws/src/stretch_ros/stretch_description/meshes/link_aruco_inner_wrist.STL</uri>
            </mesh>
          </geometry>
          <surface>
            <contact>
              <ode/>
            </contact>
            <friction>
              <ode/>
              <torsional>
                <ode/>
              </torsional>
            </friction>
            <bounce/>
          </surface>
          <max_contacts>10</max_contacts>
        </collision>
        <collision name='link_arm_l0_fixed_joint_lump__link_aruco_top_wrist_collision_2'>
          <pose>0.04725 0.029285 0 1.5708 -0 3.14159</pose>
          <geometry>
            <mesh>
              <scale>1 1 1</scale>
              <uri>/home/sandisk/koyo_ws/stretch_ws/src/stretch_ros/stretch_description/meshes/link_aruco_top_wrist.STL</uri>
            </mesh>
          </geometry>
          <surface>
            <contact>
              <ode/>
            </contact>
            <friction>
              <ode/>
              <torsional>
                <ode/>
              </torsional>
            </friction>
            <bounce/>
          </surface>
          <max_contacts>10</max_contacts>
        </collision>
        <visual name='link_arm_l0_visual'>
          <pose>0 0 0 0 -0 0</pose>
          <geometry>
            <mesh>
              <scale>1 1 1</scale>
              <uri>/home/sandisk/koyo_ws/stretch_ws/src/stretch_ros/stretch_description/meshes/link_arm_l0.STL</uri>
            </mesh>
          </geometry>
          <material>
            <script>
              <name>Gazebo/Gray</name>
              <uri>file://media/materials/scripts/gazebo.material</uri>
            </script>
          </material>
        </visual>
        <visual name='link_arm_l0_fixed_joint_lump__link_aruco_inner_wrist_visual_1'>
          <pose>0.04725 -0.0119 -0.02725 3.14159 -0 3.14159</pose>
          <geometry>
            <mesh>
              <scale>1 1 1</scale>
              <uri>/home/sandisk/koyo_ws/stretch_ws/src/stretch_ros/stretch_description/meshes/link_aruco_inner_wrist.STL</uri>
            </mesh>
          </geometry>
          <material>
            <script>
              <name>Gazebo/Black</name>
              <uri>file://media/materials/scripts/gazebo.material</uri>
            </script>
          </material>
        </visual>
        <visual name='link_arm_l0_fixed_joint_lump__link_aruco_top_wrist_visual_2'>
          <pose>0.04725 0.029285 0 1.5708 -0 3.14159</pose>
          <geometry>
            <mesh>
              <scale>1 1 1</scale>
              <uri>/home/sandisk/koyo_ws/stretch_ws/src/stretch_ros/stretch_description/meshes/link_aruco_top_wrist.STL</uri>
            </mesh>
          </geometry>
          <material>
            <script>
              <name>Gazebo/Black</name>
              <uri>file://media/materials/scripts/gazebo.material</uri>
            </script>
          </material>
        </visual>
        <self_collide>0</self_collide>
        <enable_wind>0</enable_wind>
        <kinematic>0</kinematic>
      </link>
      <joint name='joint_wrist_yaw' type='revolute'>
        <pose relative_to='link_arm_l0'>0.083 -0.03075 0 1.5708 -0 0</pose>
        <parent>link_arm_l0</parent>
        <child>link_wrist_yaw</child>
        <axis>
          <xyz>0 0 -1</xyz>
          <limit>
            <lower>-1.75</lower>
            <upper>4</upper>
            <effort>100</effort>
            <velocity>1</velocity>
          </limit>
          <dynamics>
            <spring_reference>0</spring_reference>
            <spring_stiffness>0</spring_stiffness>
          </dynamics>
        </axis>
      </joint>
      <link name='link_wrist_yaw'>
        <pose relative_to='joint_wrist_yaw'>0 0 0 0 -0 0</pose>
        <inertial>
          <pose>-0.009405 0.012192 0.021206 0 -0 0</pose>
          <mass>0.142377</mass>
          <inertia>
            <ixx>0.00209963</ixx>
            <ixy>6.46903e-06</ixy>
            <ixz>2.13665e-05</ixz>
            <iyy>0.00209626</iyy>
            <iyz>-2.76309e-05</iyz>
            <izz>0.00201337</izz>
          </inertia>
        </inertial>
        <collision name='link_wrist_yaw_collision'>
          <pose>0 0 0 0 -0 0</pose>
          <geometry>
            <mesh>
              <scale>1 1 1</scale>
              <uri>/home/sandisk/koyo_ws/stretch_ws/src/stretch_ros/stretch_description/meshes/link_wrist_yaw.STL</uri>
            </mesh>
          </geometry>
          <surface>
            <contact>
              <ode>
                <kp>1e+07</kp>
                <kd>100</kd>
                <min_depth>0.001</min_depth>
              </ode>
            </contact>
            <friction>
              <ode>
                <mu>100</mu>
                <mu2>200</mu2>
              </ode>
              <torsional>
                <ode/>
              </torsional>
            </friction>
            <bounce/>
          </surface>
          <max_contacts>10</max_contacts>
        </collision>
        <collision name='link_wrist_yaw_fixed_joint_lump__link_gripper_collision_1'>
          <pose>0 0 0 3.14159 -0 -1.5708</pose>
          <geometry>
            <mesh>
              <scale>1 1 1</scale>
              <uri>/home/sandisk/koyo_ws/stretch_ws/src/stretch_ros/stretch_description/meshes/link_gripper.STL</uri>
            </mesh>
          </geometry>
          <surface>
            <contact>
              <ode>
                <kp>1e+07</kp>
                <kd>100</kd>
                <min_depth>0.001</min_depth>
              </ode>
            </contact>
            <friction>
              <ode>
                <mu>100</mu>
                <mu2>200</mu2>
              </ode>
              <torsional>
                <ode/>
              </torsional>
            </friction>
            <bounce/>
          </surface>
          <max_contacts>10</max_contacts>
        </collision>
        <visual name='link_wrist_yaw_visual'>
          <pose>0 0 0 0 -0 0</pose>
          <geometry>
            <mesh>
              <scale>1 1 1</scale>
              <uri>/home/sandisk/koyo_ws/stretch_ws/src/stretch_ros/stretch_description/meshes/link_wrist_yaw.STL</uri>
            </mesh>
          </geometry>
          <material>
            <script>
              <name>Gazebo/Black</name>
              <uri>file://media/materials/scripts/gazebo.material</uri>
            </script>
          </material>
        </visual>
        <visual name='link_wrist_yaw_fixed_joint_lump__link_gripper_visual_1'>
          <pose>0 0 0 3.14159 -0 -1.5708</pose>
          <geometry>
            <mesh>
              <scale>1 1 1</scale>
              <uri>/home/sandisk/koyo_ws/stretch_ws/src/stretch_ros/stretch_description/meshes/link_gripper.STL</uri>
            </mesh>
          </geometry>
          <material>
            <script>
              <name>Gazebo/Gray</name>
              <uri>file://media/materials/scripts/gazebo.material</uri>
            </script>
          </material>
        </visual>
        <gravity>1</gravity>
        <sensor name='wrist_imu' type='imu'>
          <always_on>1</always_on>
          <visualize>0</visualize>
          <plugin name='imu_plugin' filename='libgazebo_ros_imu_sensor.so'>
            <topicName>wrist_imu/data</topicName>
            <bodyName>link_wrist_yaw</bodyName>
            <updateRateHZ>25.0</updateRateHZ>
            <gaussianNoise>0.001</gaussianNoise>
            <xyzOffset>0 0 0</xyzOffset>
            <rpyOffset>0 0 0</rpyOffset>
            <frameName>link_wrist_yaw</frameName>
            <initialOrientationAsReference>0</initialOrientationAsReference>
            <robotNamespace>/</robotNamespace>
          </plugin>
          <pose>0 0 0 0 -0 0</pose>
          <imu/>
        </sensor>
        <self_collide>0</self_collide>
        <enable_wind>0</enable_wind>
        <kinematic>0</kinematic>
      </link>
      <joint name='joint_gripper_finger_left' type='revolute'>
        <pose relative_to='link_wrist_yaw'>0.010151 0.047231 0.04679 -3.14159 -0.5236 1.57078</pose>
        <parent>link_wrist_yaw</parent>
        <child>link_gripper_finger_left</child>
        <axis>
          <xyz>0 0 1</xyz>
          <limit>
            <lower>-0.6</lower>
            <upper>0.6</upper>
            <effort>100</effort>
            <velocity>1</velocity>
          </limit>
          <dynamics>
            <spring_reference>0</spring_reference>
            <spring_stiffness>0</spring_stiffness>
          </dynamics>
        </axis>
      </joint>
      <link name='link_gripper_finger_left'>
        <pose relative_to='joint_gripper_finger_left'>0 0 0 0 -0 0</pose>
        <inertial>
          <pose>0.100529 0.012112 -0 0 -0 0</pose>
          <mass>0.0514424</mass>
          <inertia>
            <ixx>0.00200006</ixx>
            <ixy>1.22883e-06</ixy>
            <ixz>7.72702e-12</ixz>
            <iyy>0.00202327</iyy>
            <iyz>-4.08122e-13</iyz>
            <izz>0.00202333</izz>
          </inertia>
        </inertial>
        <collision name='link_gripper_finger_left_collision'>
          <pose>0 0 0 0 -0 0</pose>
          <geometry>
            <mesh>
              <scale>0.9 1 1</scale>
              <uri>/home/sandisk/koyo_ws/stretch_ws/src/stretch_ros/stretch_description/meshes/link_gripper_finger_left.STL</uri>
            </mesh>
          </geometry>
          <surface>
            <contact>
              <ode>
                <kp>1e+07</kp>
                <kd>100</kd>
                <min_depth>0.001</min_depth>
              </ode>
            </contact>
            <friction>
              <ode>
                <mu>100</mu>
                <mu2>200</mu2>
              </ode>
              <torsional>
                <ode/>
              </torsional>
            </friction>
            <bounce/>
          </surface>
          <max_contacts>10</max_contacts>
        </collision>
        <collision name='link_gripper_finger_left_fixed_joint_lump__link_gripper_fingertip_left_collision_1'>
          <pose>0.171099 0.014912 0 -1.5708 -0 -2.5545</pose>
          <geometry>
            <mesh>
              <scale>1 1 1</scale>
              <uri>/home/sandisk/koyo_ws/stretch_ws/src/stretch_ros/stretch_description/meshes/link_gripper_fingertip_left.STL</uri>
            </mesh>
          </geometry>
          <surface>
            <contact>
              <ode>
                <kp>1e+07</kp>
                <kd>100</kd>
                <min_depth>0.001</min_depth>
              </ode>
            </contact>
            <friction>
              <ode>
                <mu>100</mu>
                <mu2>200</mu2>
              </ode>
              <torsional>
                <ode/>
              </torsional>
            </friction>
            <bounce/>
          </surface>
          <max_contacts>10</max_contacts>
        </collision>
        <visual name='link_gripper_finger_left_visual'>
          <pose>0 0 0 0 -0 0</pose>
          <geometry>
            <mesh>
              <scale>0.9 1 1</scale>
              <uri>/home/sandisk/koyo_ws/stretch_ws/src/stretch_ros/stretch_description/meshes/link_gripper_finger_left.STL</uri>
            </mesh>
          </geometry>
          <material>
            <script>
              <name>Gazebo/Gray</name>
              <uri>file://media/materials/scripts/gazebo.material</uri>
            </script>
          </material>
        </visual>
        <visual name='link_gripper_finger_left_fixed_joint_lump__link_gripper_fingertip_left_visual_1'>
          <pose>0.171099 0.014912 0 -1.5708 -0 -2.5545</pose>
          <geometry>
            <mesh>
              <scale>1 1 1</scale>
              <uri>/home/sandisk/koyo_ws/stretch_ws/src/stretch_ros/stretch_description/meshes/link_gripper_fingertip_left.STL</uri>
            </mesh>
          </geometry>
          <material>
            <script>
              <name>Gazebo/Black</name>
              <uri>file://media/materials/scripts/gazebo.material</uri>
            </script>
          </material>
        </visual>
        <self_collide>0</self_collide>
        <enable_wind>0</enable_wind>
        <kinematic>0</kinematic>
      </link>
      <joint name='joint_gripper_finger_right' type='revolute'>
        <pose relative_to='link_wrist_yaw'>-0.010049 0.047231 0.04679 4e-06 0.5236 -1.5708</pose>
        <parent>link_wrist_yaw</parent>
        <child>link_gripper_finger_right</child>
        <axis>
          <xyz>0 0 1</xyz>
          <limit>
            <lower>-0.6</lower>
            <upper>0.6</upper>
            <effort>100</effort>
            <velocity>1</velocity>
          </limit>
          <dynamics>
            <spring_reference>0</spring_reference>
            <spring_stiffness>0</spring_stiffness>
          </dynamics>
        </axis>
      </joint>
      <link name='link_gripper_finger_right'>
        <pose relative_to='joint_gripper_finger_right'>0 0 0 0 -0 0</pose>
        <inertial>
          <pose>-0.100529 -0.012112 -0 0 -0 0</pose>
          <mass>0.0514424</mass>
          <inertia>
            <ixx>0.00200006</ixx>
            <ixy>1.22889e-06</ixy>
            <ixz>-1.04879e-11</ixz>
            <iyy>0.00202327</iyy>
            <iyz>5.53976e-13</iyz>
            <izz>0.00202333</izz>
          </inertia>
        </inertial>
        <collision name='link_gripper_finger_right_collision'>
          <pose>0 0 0 0 -0 0</pose>
          <geometry>
            <mesh>
              <scale>0.9 1 1</scale>
              <uri>/home/sandisk/koyo_ws/stretch_ws/src/stretch_ros/stretch_description/meshes/link_gripper_finger_right.STL</uri>
            </mesh>
          </geometry>
          <surface>
            <contact>
              <ode>
                <kp>1e+07</kp>
                <kd>100</kd>
                <min_depth>0.001</min_depth>
              </ode>
            </contact>
            <friction>
              <ode>
                <mu>100</mu>
                <mu2>200</mu2>
              </ode>
              <torsional>
                <ode/>
              </torsional>
            </friction>
            <bounce/>
          </surface>
          <max_contacts>10</max_contacts>
        </collision>
        <collision name='link_gripper_finger_right_fixed_joint_lump__link_gripper_fingertip_right_collision_1'>
          <pose>-0.171099 -0.014912 0 -1.5708 -0 0.58705</pose>
          <geometry>
            <mesh>
              <scale>1 1 1</scale>
              <uri>/home/sandisk/koyo_ws/stretch_ws/src/stretch_ros/stretch_description/meshes/link_gripper_fingertip_right.STL</uri>
            </mesh>
          </geometry>
          <surface>
            <contact>
              <ode>
                <kp>1e+07</kp>
                <kd>100</kd>
                <min_depth>0.001</min_depth>
              </ode>
            </contact>
            <friction>
              <ode>
                <mu>100</mu>
                <mu2>200</mu2>
              </ode>
              <torsional>
                <ode/>
              </torsional>
            </friction>
            <bounce/>
          </surface>
          <max_contacts>10</max_contacts>
        </collision>
        <visual name='link_gripper_finger_right_visual'>
          <pose>0 0 0 0 -0 0</pose>
          <geometry>
            <mesh>
              <scale>0.9 1 1</scale>
              <uri>/home/sandisk/koyo_ws/stretch_ws/src/stretch_ros/stretch_description/meshes/link_gripper_finger_right.STL</uri>
            </mesh>
          </geometry>
          <material>
            <script>
              <name>Gazebo/Gray</name>
              <uri>file://media/materials/scripts/gazebo.material</uri>
            </script>
          </material>
        </visual>
        <visual name='link_gripper_finger_right_fixed_joint_lump__link_gripper_fingertip_right_visual_1'>
          <pose>-0.171099 -0.014912 0 -1.5708 -0 0.58705</pose>
          <geometry>
            <mesh>
              <scale>1 1 1</scale>
              <uri>/home/sandisk/koyo_ws/stretch_ws/src/stretch_ros/stretch_description/meshes/link_gripper_fingertip_right.STL</uri>
            </mesh>
          </geometry>
          <material>
            <script>
              <name>Gazebo/Black</name>
              <uri>file://media/materials/scripts/gazebo.material</uri>
            </script>
          </material>
        </visual>
        <self_collide>0</self_collide>
        <enable_wind>0</enable_wind>
        <kinematic>0</kinematic>
      </link>
      <joint name='joint_right_wheel' type='revolute'>
        <pose relative_to='base_link'>0 -0.17035 0.0508 -1.5708 0 0</pose>
        <parent>base_link</parent>
        <child>link_right_wheel</child>
        <axis>
          <xyz>0 0 1</xyz>
          <limit>
            <lower>-1e+16</lower>
            <upper>1e+16</upper>
          </limit>
          <dynamics>
            <damping>21.75</damping>
            <friction>10.48</friction>
            <spring_reference>0</spring_reference>
            <spring_stiffness>0</spring_stiffness>
          </dynamics>
        </axis>
      </joint>
      <link name='link_right_wheel'>
        <pose relative_to='joint_right_wheel'>0 0 0 0 -0 0</pose>
        <inertial>
          <pose>0 0 0.037544 0 -0 0</pose>
          <mass>0.0042721</mass>
          <inertia>
            <ixx>0.001</ixx>
            <ixy>0</ixy>
            <ixz>0</ixz>
            <iyy>0.001</iyy>
            <iyz>0</iyz>
            <izz>0.001</izz>
          </inertia>
        </inertial>
        <collision name='link_right_wheel_collision'>
          <pose>0 0 0 0 -0 0</pose>
          <geometry>
            <mesh>
              <scale>1 1 1</scale>
              <uri>/home/sandisk/koyo_ws/stretch_ws/src/stretch_ros/stretch_description/meshes/link_right_wheel.STL</uri>
            </mesh>
          </geometry>
          <surface>
            <contact>
              <ode>
                <kp>1e+07</kp>
                <kd>100</kd>
                <min_depth>0.001</min_depth>
              </ode>
            </contact>
            <friction>
              <ode>
                <mu>100</mu>
                <mu2>200</mu2>
              </ode>
              <torsional>
                <ode/>
              </torsional>
            </friction>
            <bounce/>
          </surface>
          <max_contacts>10</max_contacts>
        </collision>
        <visual name='link_right_wheel_visual'>
          <pose>0 0 0 0 -0 0</pose>
          <geometry>
            <mesh>
              <scale>1 1 1</scale>
              <uri>/home/sandisk/koyo_ws/stretch_ws/src/stretch_ros/stretch_description/meshes/link_right_wheel.STL</uri>
            </mesh>
          </geometry>
          <material>
            <script>
              <name>Gazebo/Blue</name>
              <uri>file://media/materials/scripts/gazebo.material</uri>
            </script>
          </material>
        </visual>
        <self_collide>0</self_collide>
        <enable_wind>0</enable_wind>
        <kinematic>0</kinematic>
      </link>
      <plugin name='gazebo_ros_control' filename='libgazebo_ros_control.so'>
        <robotNamespace>/</robotNamespace>
      </plugin>
      <plugin name='camera' filename='librealsense_gazebo_plugin.so'>
        <depthUpdateRate>30</depthUpdateRate>
        <colorUpdateRate>30</colorUpdateRate>
        <infraredUpdateRate>30</infraredUpdateRate>
        <depthTopicName>depth/image_raw</depthTopicName>
        <depthCameraInfoTopicName>depth/camera_info</depthCameraInfoTopicName>
        <colorTopicName>color/image_raw</colorTopicName>
        <colorCameraInfoTopicName>color/camera_info</colorCameraInfoTopicName>
        <infrared1TopicName>infrared/image_raw</infrared1TopicName>
        <infrared1CameraInfoTopicName>infrared/camera_info</infrared1CameraInfoTopicName>
        <infrared2TopicName>infrared2/image_raw</infrared2TopicName>
        <infrared2CameraInfoTopicName>infrared2/camera_info</infrared2CameraInfoTopicName>
        <colorOpticalframeName>camera_color_optical_frame</colorOpticalframeName>
        <depthOpticalframeName>camera_depth_optical_frame</depthOpticalframeName>
        <infrared1OpticalframeName>camera_left_ir_optical_frame</infrared1OpticalframeName>
        <infrared2OpticalframeName>camera_right_ir_optical_frame</infrared2OpticalframeName>
        <rangeMinDepth>0.1</rangeMinDepth>
        <rangeMaxDepth>10</rangeMaxDepth>
        <pointCloud>1</pointCloud>
        <pointCloudTopicName>depth/color/points</pointCloudTopicName>
        <pointCloudCutoff>0.15</pointCloudCutoff>
        <pointCloudCutoffMax>10</pointCloudCutoffMax>
        <robotNamespace>/</robotNamespace>
      </plugin>
      <frame name='caster_joint' attached_to='base_link'>
        <pose>-0.245 0 0.032 -1.5708 0 0</pose>
      </frame>
      <frame name='caster_link' attached_to='caster_joint'/>
      <frame name='joint_aruco_left_base' attached_to='base_link'>
        <pose>-0.005 0.130497 0.159748 0 0 -1.5708</pose>
      </frame>
      <frame name='link_aruco_left_base' attached_to='joint_aruco_left_base'/>
      <frame name='joint_aruco_right_base' attached_to='base_link'>
        <pose>-0.001503 -0.130497 0.159748 0 0 -1.5708</pose>
      </frame>
      <frame name='link_aruco_right_base' attached_to='joint_aruco_right_base'/>
      <frame name='joint_laser' attached_to='base_link'>
        <pose>0.004 0 0.1664 0 -0 -3.14159</pose>
      </frame>
      <frame name='laser' attached_to='joint_laser'/>
      <frame name='joint_head' attached_to='link_mast'>
        <pose>0 1.33 0 1.5708 -1.57079 3.14159</pose>
      </frame>
      <frame name='link_head' attached_to='joint_head'/>
      <frame name='camera_accel_optical_joint' attached_to='camera_accel_frame'>
        <pose>0 0 0 -1.5708 -0 -1.5708</pose>
      </frame>
      <frame name='camera_accel_optical_frame' attached_to='camera_accel_optical_joint'/>
      <frame name='camera_accel_joint' attached_to='camera_link'>
        <pose>-0.01174 -0.00552 0.0051 0 -0 0</pose>
      </frame>
      <frame name='camera_accel_frame' attached_to='camera_accel_joint'/>
      <frame name='camera_color_optical_joint' attached_to='camera_color_frame'>
        <pose>0 0 0 -1.5708 -0 -1.5708</pose>
      </frame>
      <frame name='camera_color_optical_frame' attached_to='camera_color_optical_joint'/>
      <frame name='camera_color_joint' attached_to='camera_link'>
        <pose>0 0.015 0 0 -0 0</pose>
      </frame>
      <frame name='camera_color_frame' attached_to='camera_color_joint'/>
      <frame name='camera_depth_optical_joint' attached_to='camera_depth_frame'>
        <pose>0 0 0 -1.5708 -0 -1.5708</pose>
      </frame>
      <frame name='camera_depth_optical_frame' attached_to='camera_depth_optical_joint'/>
      <frame name='camera_depth_joint' attached_to='camera_link'>
        <pose>0 0 0 0 -0 0</pose>
      </frame>
      <frame name='camera_depth_frame' attached_to='camera_depth_joint'/>
      <frame name='camera_gyro_optical_joint' attached_to='camera_gyro_frame'>
        <pose>0 0 0 -1.5708 -0 -1.5708</pose>
      </frame>
      <frame name='camera_gyro_optical_frame' attached_to='camera_gyro_optical_joint'/>
      <frame name='camera_gyro_joint' attached_to='camera_link'>
        <pose>-0.01174 -0.00552 0.0051 0 -0 0</pose>
      </frame>
      <frame name='camera_gyro_frame' attached_to='camera_gyro_joint'/>
      <frame name='camera_infra1_optical_joint' attached_to='camera_infra1_frame'>
        <pose>0 0 0 -1.5708 -0 -1.5708</pose>
      </frame>
      <frame name='camera_infra1_optical_frame' attached_to='camera_infra1_optical_joint'/>
      <frame name='camera_infra1_joint' attached_to='camera_link'>
        <pose>0 0 0 0 -0 0</pose>
      </frame>
      <frame name='camera_infra1_frame' attached_to='camera_infra1_joint'/>
      <frame name='camera_infra2_optical_joint' attached_to='camera_infra2_frame'>
        <pose>0 0 0 -1.5708 -0 -1.5708</pose>
      </frame>
      <frame name='camera_infra2_optical_frame' attached_to='camera_infra2_optical_joint'/>
      <frame name='camera_infra2_joint' attached_to='camera_link'>
        <pose>0 -0.05 0 0 -0 0</pose>
      </frame>
      <frame name='camera_infra2_frame' attached_to='camera_infra2_joint'/>
      <frame name='camera_link_joint' attached_to='camera_bottom_screw_frame'>
        <pose>0.0106 0.0175 0.0125 0 -0 0</pose>
      </frame>
      <frame name='camera_link' attached_to='camera_link_joint'/>
      <frame name='camera_joint' attached_to='link_head_tilt'>
        <pose>0.03 -0.0122 0.0182 0 -0 0</pose>
      </frame>
      <frame name='camera_bottom_screw_frame' attached_to='camera_joint'/>
      <frame name='joint_respeaker' attached_to='link_mast'>
        <pose>0 1.37236 0.003031 -1.5708 -0.698132 -0</pose>
      </frame>
      <frame name='respeaker_base' attached_to='joint_respeaker'/>
      <frame name='joint_mast' attached_to='base_link'>
        <pose>-0.067 0.135 0.0284 1.5708 -0 0</pose>
      </frame>
      <frame name='link_mast' attached_to='joint_mast'/>
      <frame name='joint_arm_l4' attached_to='link_lift'>
        <pose>-0.2547 0 0 1.5708 0 -1.5708</pose>
      </frame>
      <frame name='link_arm_l4' attached_to='joint_arm_l4'/>
      <frame name='joint_aruco_inner_wrist' attached_to='link_arm_l0'>
        <pose>0.04725 -0.0119 -0.02725 3.14159 -0 3.14159</pose>
      </frame>
      <frame name='link_aruco_inner_wrist' attached_to='joint_aruco_inner_wrist'/>
      <frame name='joint_aruco_top_wrist' attached_to='link_arm_l0'>
        <pose>0.04725 0.029285 0 1.5708 -0 3.14159</pose>
      </frame>
      <frame name='link_aruco_top_wrist' attached_to='joint_aruco_top_wrist'/>
      <frame name='joint_grasp_center' attached_to='link_gripper'>
        <pose>-0.205478 0 -0.138154 0 -0 3.14158</pose>
      </frame>
      <frame name='link_grasp_center' attached_to='joint_grasp_center'/>
      <frame name='joint_gripper' attached_to='link_wrist_yaw'>
        <pose>0 0 0 3.14159 -0 -1.5708</pose>
      </frame>
      <frame name='link_gripper' attached_to='joint_gripper'/>
      <frame name='joint_gripper_fingertip_left' attached_to='link_gripper_finger_left'>
        <pose>0.171099 0.014912 0 -1.5708 -0 -2.5545</pose>
      </frame>
      <frame name='link_gripper_fingertip_left' attached_to='joint_gripper_fingertip_left'/>
      <frame name='joint_gripper_fingertip_right' attached_to='link_gripper_finger_right'>
        <pose>-0.171099 -0.014912 0 -1.5708 -0 0.58705</pose>
      </frame>
      <frame name='link_gripper_fingertip_right' attached_to='joint_gripper_fingertip_right'/>
      <frame name='joint_aruco_shoulder' attached_to='link_lift'>
        <pose>-0.013377 0.055854 0.086137 0 -0 0</pose>
      </frame>
      <frame name='link_aruco_shoulder' attached_to='joint_aruco_shoulder'/>
      <pose>0 0 0 0 -0 0</pose>
    </model>
    <model name='person_walking'>
      <link name='link'>
        <inertial>
          <pose>0 0 0.95 0 -0 0</pose>
          <mass>80</mass>
          <inertia>
            <ixx>27.82</ixx>
            <ixy>0</ixy>
            <ixz>0</ixz>
            <iyy>24.88</iyy>
            <iyz>0</iyz>
            <izz>4.57</izz>
          </inertia>
        </inertial>
        <collision name='bottom'>
          <pose>0 0 0.01 0 -0 0</pose>
          <geometry>
            <box>
              <size>0.35 0.75 0.02</size>
            </box>
          </geometry>
          <max_contacts>10</max_contacts>
          <surface>
            <contact>
              <ode/>
            </contact>
            <bounce/>
            <friction>
              <torsional>
                <ode/>
              </torsional>
              <ode/>
            </friction>
          </surface>
        </collision>
        <collision name='person'>
          <pose>0 0 -0.02 0 -0 0</pose>
          <geometry>
            <mesh>
              <uri>https://fuel.ignitionrobotics.org/1.0/gazebomstrling/models/walking person/1/files/meshes/walking.dae</uri>
            </mesh>
          </geometry>
          <max_contacts>10</max_contacts>
          <surface>
            <contact>
              <ode/>
            </contact>
            <bounce/>
            <friction>
              <torsional>
                <ode/>
              </torsional>
              <ode/>
            </friction>
          </surface>
        </collision>
        <visual name='visual'>
          <pose>0 0 -0.02 0 -0 0</pose>
          <geometry>
            <mesh>
              <uri>https://fuel.ignitionrobotics.org/1.0/gazebomstrling/models/walking person/1/files/meshes/walking.dae</uri>
            </mesh>
          </geometry>
        </visual>
        <self_collide>0</self_collide>
        <enable_wind>0</enable_wind>
        <kinematic>0</kinematic>
      </link>
      <!-- <pose>-0.257479 -1.21111 0 0 -0 0</pose> -->
      <pose>0.420835 -4.00989 1.5 0 -0 0</pose>
    </model>
    <state world_name='default'>
      <sim_time>183 408000000</sim_time>
      <real_time>288 565398501</real_time>
      <wall_time>1747271842 920912129</wall_time>
      <iterations>74904</iterations>
      <model name='ground_plane'>
        <pose>0 0 0 0 -0 0</pose>
        <scale>1 1 1</scale>
        <link name='link'>
          <pose>0 0 0 0 -0 0</pose>
          <velocity>0 0 0 0 -0 0</velocity>
          <acceleration>0 0 0 0 -0 0</acceleration>
          <wrench>0 0 0 0 -0 0</wrench>
        </link>
      </model>
      <model name='person_walking'>
        <pose>0.274011 -1.22229 0 1e-06 1e-06 3.12627</pose>
        <scale>1 1 1</scale>
        <link name='link'>
          <pose>0.274011 -1.22229 0 1e-06 1e-06 3.12627</pose>
          <velocity>0 0 0 0 -0 0</velocity>
          <acceleration>1.6064 -3.62007 2.72127 0.572634 1.22171 -3.03648</acceleration>
          <wrench>128.512 -289.606 217.702 0 -0 0</wrench>
        </link>
      </model>
      <model name='robot'>
        <pose>0.082231 0.060853 -0.00042 -0.000809 0.001715 0.16375</pose>
        <scale>1 1 1</scale>
        <link name='base_link'>
          <pose>0.082231 0.060853 -0.00042 -0.000809 0.001715 0.16375</pose>
          <velocity>0.000953 0.001571 0.00029 0.002329 -0.000874 0.000973</velocity>
          <acceleration>0.25811 0.029843 0.625788 -1.70078 0.573676 2.4321</acceleration>
          <wrench>0.83973 0.097089 2.03593 0 -0 0</wrench>
        </link>
        <link name='link_arm_l0'>
          <pose>0.003974 -0.098429 0.694864 1.57009 0.001738 0.16384</pose>
          <velocity>0.000499 0.000979 -0.00012 0.000321 0.00178 0.001541</velocity>
          <acceleration>-0.317268 -0.064557 -0.004012 -0.149484 -1.41087 -1.71112</acceleration>
          <wrench>-0.026969 -0.005488 -0.000341 0 -0 0</wrench>
        </link>
        <link name='link_arm_l1'>
          <pose>0.006216 -0.111995 0.694874 1.57007 0.001735 0.163831</pose>
          <velocity>0.000526 0.000977 -0.000152 0.000622 0.001589 0.00158</velocity>
          <acceleration>-0.358924 -0.089361 0.067008 -0.118524 -1.46987 -2.34277</acceleration>
          <wrench>-0.018442 -0.004592 0.003443 0 -0 0</wrench>
        </link>
        <link name='link_arm_l2'>
          <pose>0.004094 -0.09917 0.694867 1.57006 0.001731 0.163815</pose>
          <velocity>0.000547 0.00063 -0.000171 0.000983 0.00137 0.001576</velocity>
          <acceleration>-0.449431 -0.079329 0.149494 -0.187264 -1.3895 3.01389</acceleration>
          <wrench>-0.02568 -0.004533 0.008542 0 -0 0</wrench>
        </link>
        <link name='link_arm_l3'>
          <pose>0.001973 -0.086344 0.694859 1.57004 0.001726 0.163797</pose>
          <velocity>0.000565 0.000278 -0.00019 0.001393 0.00111 0.001565</velocity>
          <acceleration>-0.525998 -0.063423 0.230782 -0.27115 -1.27015 1.94935</acceleration>
          <wrench>-0.033081 -0.003989 0.014515 0 -0 0</wrench>
        </link>
        <link name='link_gripper_finger_left'>
          <pose>0.103457 -0.129912 0.617197 0.267983 0.454581 -0.84507</pose>
          <velocity>0.000424 0.001178 -0.000293 0.000352 0.001839 0.001544</velocity>
          <acceleration>0.03066 0.4225 -0.137367 -0.1535 -1.38545 -1.78203</acceleration>
          <wrench>0.001577 0.021734 -0.007066 0 -0 0</wrench>
        </link>
        <link name='link_gripper_finger_right'>
          <pose>0.083527 -0.133207 0.617232 -2.87034 -0.452725 1.17134</pose>
          <velocity>0.000432 0.00115 -0.000255 0.000412 0.001973 0.001184</velocity>
          <acceleration>0.03061 0.226303 -0.435044 -0.168439 -1.35329 -1.95498</acceleration>
          <wrench>0.001575 0.011642 -0.02238 0 -0 0</wrench>
        </link>
        <link name='link_head_pan'>
          <pose>0.090368 0.063305 1.35477 -0.001759 -0.000682 -1.33624</pose>
          <velocity>6.1e-05 -0.001421 0.000227 0.002448 -0.000996 0.002341</velocity>
          <acceleration>-2.58366 -1.7567 0.879696 -1.74493 0.363558 -1.13702</acceleration>
          <wrench>-0.070731 -0.048092 0.024083 0 -0 0</wrench>
        </link>
        <link name='link_head_tilt'>
          <pose>0.116984 0.070964 1.30141 1.5688 0.499317 -1.3372</pose>
          <velocity>2.6e-05 -0.001279 0.0003 0.00247 -0.000961 0.002209</velocity>
          <acceleration>-2.47419 -1.60407 0.857679 -2.60098 0.892908 -1.21588</acceleration>
          <wrench>-0.401356 -0.260208 0.13913 0 -0 0</wrench>
        </link>
        <link name='link_left_wheel'>
          <pose>0.054532 0.228967 0.050632 -1.57155 0.052636 0.163715</pose>
          <velocity>-5.6e-05 -0.000262 0.026707 0.006105 -0.001359 0.001202</velocity>
          <acceleration>-0.226735 -0.060878 1.44697 -1.72538 -0.199039 -1.11213</acceleration>
          <wrench>-0.000969 -0.00026 0.006182 0 -0 0</wrench>
        </link>
        <link name='link_lift'>
          <pose>-0.041676 0.177773 0.694649 0.001731 0.000788 1.73458</pose>
          <velocity>0.000192 -0.000108 0.000273 0.001666 0.000955 0.001525</velocity>
          <acceleration>-0.364606 0.069899 0.479606 -0.644481 1.48032 0.002116</acceleration>
          <wrench>-0.124066 0.023785 0.163198 0 -0 0</wrench>
        </link>
        <link name='link_right_wheel'>
          <pose>0.110075 -0.107164 0.050631 -1.57163 0.03052 0.163724</pose>
          <velocity>3.5e-05 -1e-05 0.007804 0.000645 -4.7e-05 0.000774</velocity>
          <acceleration>-1.28879 -0.984923 34.7094 -0.986012 0.148951 -2.19416</acceleration>
          <wrench>-0.005506 -0.004208 0.148282 0 -0 0</wrench>
        </link>
        <link name='link_wrist_yaw'>
          <pose>0.085813 -0.084923 0.663971 3.14089 0.001738 0.163842</pose>
          <velocity>0.000432 0.001133 -0.000246 0.000328 0.001777 0.001703</velocity>
          <acceleration>-0.206606 0.085067 -0.027844 -0.121155 -1.45781 -1.64545</acceleration>
          <wrench>-0.029416 0.012112 -0.003964 0 -0 0</wrench>
        </link>
      </model>
      <model name='unit_box'>
        <pose>-1.60667 -0.17696 0.177143 -0 0.005081 -1.57055</pose>
        <scale>2.93481 1.36944 0.369183</scale>
        <link name='link'>
          <pose>-1.60667 -0.17696 0.177143 -0 0.005081 -1.57055</pose>
          <velocity>0.000662 0.013762 -0.261923 0.18543 4.5e-05 0.000445</velocity>
          <acceleration>-0.021544 -9.69841 -0.101588 0.082555 0.089432 0.917334</acceleration>
          <wrench>-0.10772 -48.4921 -0.507942 0 -0 0</wrench>
        </link>
      </model>
      <model name='unit_box_clone'>
        <pose>-2.50874 0.647697 0.681982 -1.57084 -0.001877 -1.54834</pose>
        <scale>1 1 1</scale>
        <link name='link'>
          <pose>-2.50874 0.647697 0.681982 -1.57084 -0.001877 -1.54834</pose>
          <velocity>0.000804 0.073716 -0.156361 -0.114232 0.000735 -0.000204</velocity>
          <acceleration>-0.005323 9.76538 -0.034623 -2.03779 0.60514 -0.694793</acceleration>
          <wrench>-0.026613 48.8269 -0.173114 0 -0 0</wrench>
        </link>
      </model>
      <light name='sun'>
        <pose>0 0 10 0 -0 0</pose>
      </light>
    </state>
    <gui fullscreen='0'>
      <camera name='user_camera'>
        <pose>0.275117 -4.42842 1.35889 0 0.203643 1.8842</pose>
        <view_controller>orbit</view_controller>
        <projection_type>perspective</projection_type>
      </camera>
    </gui>
    <model name='unit_box'>
      <pose>0.420835 -4.00989 0.5 0 -0 0</pose>
      <link name='link'>
        <inertial>
          <mass>5</mass>
          <inertia>
            <ixx>0.166667</ixx>
            <ixy>0</ixy>
            <ixz>0</ixz>
            <iyy>0.166667</iyy>
            <iyz>0</iyz>
            <izz>0.166667</izz>
          </inertia>
          <pose>0 0 0 0 -0 0</pose>
        </inertial>
        <collision name='collision'>
          <geometry>
            <box>
              <size>1 1 1</size>
            </box>
          </geometry>
          <max_contacts>10</max_contacts>
          <surface>
            <contact>
              <ode/>
            </contact>
            <bounce/>
            <friction>
              <torsional>
                <ode/>
              </torsional>
              <ode/>
            </friction>
          </surface>
        </collision>
        <visual name='visual'>
          <geometry>
            <box>
              <size>1 1 1</size>
            </box>
          </geometry>
          <material>
            <script>
              <name>Gazebo/Grey</name>
              <uri>file://media/materials/scripts/gazebo.material</uri>
            </script>
          </material>
        </visual>
        <self_collide>0</self_collide>
        <enable_wind>0</enable_wind>
        <kinematic>0</kinematic>
      </link>
    </model>
    <model name='unit_box_clone'>
      <pose>0.203647 -5.72231 0.184581 -1.5e-05 -0 -1.6e-05</pose>
      <link name='link'>
        <inertial>
          <mass>5</mass>
          <inertia>
            <ixx>0.166667</ixx>
            <ixy>0</ixy>
            <ixz>0</ixz>
            <iyy>0.166667</iyy>
            <iyz>0</iyz>
            <izz>0.166667</izz>
          </inertia>
          <pose>0 0 0 0 -0 0</pose>
        </inertial>
        <collision name='collision'>
          <geometry>
            <box>
              <size>2.93482 1.36944 0.369183</size>
            </box>
          </geometry>
          <max_contacts>10</max_contacts>
          <surface>
            <contact>
              <ode/>
            </contact>
            <bounce/>
            <friction>
              <torsional>
                <ode/>
              </torsional>
              <ode/>
            </friction>
          </surface>
        </collision>
        <visual name='visual'>
          <geometry>
            <box>
              <size>2.93482 1.36944 0.369183</size>
            </box>
          </geometry>
          <material>
            <script>
              <name>Gazebo/Grey</name>
              <uri>file://media/materials/scripts/gazebo.material</uri>
            </script>
          </material>
        </visual>
        <self_collide>0</self_collide>
        <enable_wind>0</enable_wind>
        <kinematic>0</kinematic>
      </link>
    </model>
  </world>
</sdf>
